Workbook

Sheet Start Here
A1: Debt Payoff Planner — Snowball & Avalanche
A2: Put your debts in, pick a method, get a real payoff date.
B4: WHAT'S INSIDE
B5: • Start Here — this page.
B6: • Your Debts — up to 8 debts, with automatic payoff ordering.
B7: • Payoff Plan — 180-month schedule with rollover payments built in.
B8: • Summary — debt-free date, total interest, total repaid, and a balance chart.
B10: HOW TO USE IT
B11: 1. List your debts on the Your Debts tab — name, balance, rate and minimum payment.
B12: 2. Pick Snowball (smallest balance first) or Avalanche (highest rate first) from the drop-down.
B13: 3. Enter any extra amount you can pay each month on top of the minimums.
B14: 4. Read the Summary tab: your debt-free date and total interest.
B15: 5. Open Payoff Plan for the month-by-month schedule you can actually follow.
B17: COLOUR KEY
... B25: Questions or a problem with the file? Message me through Etsy and I will help.

Sheet Your Debts
A1: Your Debts
A2: List up to 8 debts. Order does not matter — the plan sorts them for you.
A4: Debt name | B4: Balance owing | C4: Interest rate (APR) | D4: Minimum payment | E4: Sort key | F4: Payoff order | G4: Position
A5: Visa credit card | B5: 6400 | C5: 0.1999 | D5: 160 | E5: =IF(OR($A5="",N($B5)<=0),9999999,IF($B$16="Snowball",$B5,1000000-N($C5)*1000000)) | F5: =IF(E5=9999999,"—",RANK.EQ(E5,$E$5:$E$12,1)+COUNTIF($E$5:E5,E5)-1) | G5: =IFERROR(MATCH(1,$F$5:$F$12,0),0)
A6: Store card | B6: 1850 | C6: 0.2799 | D6: 60 | E6: =IF(OR($A6="",N($B6)<=0),9999999,IF($B$16="Snowball",$B6,1000000-N($C6)*1000000)) | F6: =IF(E6=9999999,"—",RANK.EQ(E6,$E$5:$E$12,1)+COUNTIF($E$5:E6,E6)-1) | G6: =IFERROR(MATCH(2,$F$5:$F$12,0),0)
A7: Car loan | B7: 14200 | C7: 0.0689 | D7: 385 | E7: =IF(OR($A7="",N($B7)<=0),9999999,IF($B$16="Snowball",$B7,1000000-N($C7)*1000000)) | F7: =IF(E7=9999999,"—",RANK.EQ(E7,$E$5:$E$12,1)+COUNTIF($E$5:E7,E7)-1) | G7: =IFERROR(MATCH(3,$F$5:$F$12,0),0)
A8: Student loan | B8: 9800 | C8: 0.0545 | D8: 210 | E8: =IF(OR($A8="",N($B8)<=0),9999999,IF($B$16="Snowball",$B8,1000000-N($C8)*1000000)) | F8: =IF(E8=9999999,"—",RANK.EQ(E8,$E$5:$E$12,1)+COUNTIF($E$5:E8,E8)-1) | G8: =IFERROR(MATCH(4,$F$5:$F$12,0),0)
A9: Line of credit | B9: 5200 | C9: 0.1145 | D9: 130 | E9: =IF(OR($A9="",N($B9)<=0),9999999,IF($B$16="Snowball",$B9,1000000-N($C9)*1000000)) | F9: =IF(E9=9999999,"—",RANK.EQ(E9,$E$5:$E$12,1)+COUNTIF($E$5:E9,E9)-1) | G9: =IFERROR(MATCH(5,$F$5:$F$12,0),0)
E10: =IF(OR($A10="",N($B10)<=0),9999999,IF($B$16="Snowball",$B10,1000000-N($C10)*1000000)) | F10: =IF(E10=9999999,"—",RANK.EQ(E10,$E$5:$E$12,1)+COUNTIF($E$5:E10,E10)-1) | G10: =IFERROR(MATCH(6,$F$5:$F$12,0),0)
E11: =IF(OR($A11="",N($B11)<=0),9999999,IF($B$16="Snowball",$B11,1000000-N($C11)*1000000)) | F11: =IF(E11=9999999,"—",RANK.EQ(E11,$E$5:$E$12,1)+COUNTIF($E$5:E11,E11)-1) | G11: =IFERROR(MATCH(7,$F$5:$F$12,0),0)
E12: =IF(OR($A12="",N($B12)<=0),9999999,IF($B$16="Snowball",$B12,1000000-N($C12)*1000000)) | F12: =IF(E12=9999999,"—",RANK.EQ(E12,$E$5:$E$12,1)+COUNTIF($E$5:E12,E12)-1) | G12: =IFERROR(MATCH(8,$F$5:$F$12,0),0)
A13: Total owing | B13: =SUM(B5:B12) | C13: Total minimums | D13: =SUM(D5:D12)
A15: YOUR PLAN
A16: Method | B16: Snowball | C16: Snowball = smallest balance first (fastest wins). Avalanche = highest rate first (cheapest).
A17: Extra payment per month | B17: 250
A18: Total monthly budget | B18: =D13+B17
A19: First payment month | B19: 2026-01-01
A21: Type the method exactly as Snowball or Avalanche — the drop-down keeps it clean.
A22: Extra payment is anything you can add on top of the minimums. Try changing it and watch the payoff date move.

Sheet Payoff Plan
A1: Payoff Plan
A2: Month-by-month. Freed-up minimums roll onto the next debt automatically.
A4: Payoff order → | D4: =IF('Your Debts'!$G$5=0,"—",INDEX('Your Debts'!$A$5:$A$12,'Your Debts'!$G$5)) | G4: =IF('Your Debts'!$G$6=0,"—",INDEX('Your Debts'!$A$5:$A$12,'Your Debts'!$G$6)) | J4: =IF('Your Debts'!$G$7=0,"—",INDEX('Your Debts'!$A$5:$A$12,'Your Debts'!$G$7)) | M4: =IF('Your Debts'!$G$8=0,"—",INDEX('Your Debts'!$A$5:$A$12,'Your Debts'!$G$8)) | P4: =IF('Your Debts'!$G$9=0,"—",INDEX('Your Debts'!$A$5:$A$12,'Your Debts'!$G$9)) | S4: =IF('Your Debts'!$G$10=0,"—",INDEX('Your Debts'!$A$5:$A$12,'Your Debts'!$G$10)) | V4: =IF('Your Debts'!$G$11=0,"—",INDEX('Your Debts'!$A$5:$A$12,'Your Debts'!$G$11)) | Y4: =IF('Your Debts'!$G$12=0,"—",INDEX('Your Debts'!$A$5:$A$12,'Your Debts'!$G$12))
A5: Month | B5: Date | C5: Budget | D5: Interest | E5: Payment | F5: Balance | G5: Interest | H5: Payment | I5: Balance | J5: Interest | K5: Payment | L5: Balance | M5: Interest | N5: Payment | O5: Balance | P5: Interest | Q5: Payment | R5: Balance | S5: Interest | T5: Payment | U5: Balance | V5: Interest | W5: Payment | X5: Balance | Y5: Interest | Z5: Payment | AA5: Balance | AB5: Total balance | AC5: Interest paid to date
A6: 1 | B6: =EDATE('Your Debts'!$B$19,0) | C6: ='Your Debts'!$B$18 | D6: =ROUND((IF('Your Debts'!$G$5=0,0,INDEX('Your Debts'!$B$5:$B$12,'Your Debts'!$G$5)))*(IF('Your Debts'!$G$5=0,0,INDEX('Your Debts'!$C$5:$C$12,'Your Debts'!$G$5)/12)),2) | E6: =MIN((IF('Your Debts'!$G$5=0,0,INDEX('Your Debts'!$B$5:$B$12,'Your Debts'!$G$5)))+D6,MAX(0,$C6-(0))) | F6: =ROUND(MAX(0,(IF('Your Debts'!$G$5=0,0,INDEX('Your Debts'!$B$5:$B$12,'Your Debts'!$G$5)))+D6-E6),2) | G6: =ROUND((IF('Your Debts'!$G$6=0,0,INDEX('Your Debts'!$B$5:$B$12,'Your Debts'!$G$6)))*(IF('Your Debts'!$G$6=0,0,INDEX('Your Debts'!$C$5:$C$12,'Your Debts'!$G$6)/12)),2) | H6: =MIN((IF('Your Debts'!$G$6=0,0,INDEX('Your Debts'!$B$5:$B$12,'Your Debts'!$G$6)))+G6,MAX(0,$C6-(E6))) | I6: =ROUND(MAX(0,(IF('Your Debts'!$G$6=0,0,INDEX('Your Debts'!$B$5:$B$12,'Your Debts'!$G$6)))+G6-H6),2) | J6: =ROUND((IF('Your Debts'!$G$7=0,0,INDEX('Your Debts'!$B$5:$B$12,'Your Debts'!$G$7)))*(IF('Your Debts'!$G$7=0,0,INDEX('Your Debts'!$C$5:$C$12,'Your Debts'!$G$7)/12)),2) | K6: =MIN((IF('Your Debts'!$G$7=0,0,INDEX('Your Debts'!$B$5:$B$12,'Your Debts'!$G$7)))+J6,MAX(0,$C6-(E6+H6))) | L6: =ROUND(MAX(0,(IF('Your Debts'!$G$7=0,0,INDEX('Your Debts'!$B$5:$B$12,'Your Debts'!$G$7)))+J6-K6),2) | M6: =ROUND((IF('Your Debts'!$G$8=0,0,INDEX('Your Debts'!$B$5:$B$12,'Your Debts'!$G$8)))*(IF('Your Debts'!$G$8=0,0,INDEX('Your Debts'!$C$5:$C$12,'Your Debts'!$G$8)/12)),2) | N6: =MIN((IF('Your Debts'!$G$8=0,0,INDEX('Your Debts'!$B$5:$B$12,'Your Debts'!$G$8)))+M6,MAX(0,$C6-(E6+H6+K6))) | O6: =ROUND(MAX(0,(IF('Your Debts'!$G$8=0,0,INDEX('Your Debts'!$B$5:$B$12,'Your Debts'!$G$8)))+M6-N6),2) | P6: =ROUND((IF('Your Debts'!$G$9=0,0,INDEX('Your Debts'!$B$5:$B$12,'Your Debts'!$G$9)))*(IF('Your Debts'!$G$9=0,0,INDEX('Your Debts'!$C$5:$C$12,'Your Debts'!$G$9)/12)),2) | Q6: =MIN((IF('Your Debts'!$G$9=0,0,INDEX('Your Debts'!$B$5:$B$12,'Your Debts'!$G$9)))+P6,MAX(0,$C6-(E6+H6+K6+N6))) | R6: =ROUND(MAX(0,(IF('Your Debts'!$G$9=0,0,INDEX('Your Debts'!$B$5:$B$12,'Your Debts'!$G$9)))+P6-Q6),2) | S6: =ROUND((IF('Your Debts'!$G$10=0,0,INDEX('Your Debts'!$B$5:$B$12,'Your Debts'!$G$10)))*(IF('Your Debts'!$G$10=0,0,INDEX('Your Debts'!$C$5:$C$12,'Your Debts'!$G$10)/12)),2) | T6: =MIN((IF('Your Debts'!$G$10=0,0,INDEX('Your Debts'!$B$5:$B$12,'Your Debts'!$G$10)))+S6,MAX(0,$C6-(E6+H6+K6+N6+Q6))) | U6: =ROUND(MAX(0,(IF('Your Debts'!$G$10=0,0,INDEX('Your Debts'!$B$5:$B$12,'Your Debts'!$G$10)))+S6-T6),2) | V6: =ROUND((IF('Your Debts'!$G$11=0,0,INDEX('Your Debts'!$B$5:$B$12,'Your Debts'!$G$11)))*(IF('Your Debts'!$G$11=0,0,INDEX('Your Debts'!$C$5:$C$12,'Your Debts'!$G$11)/12)),2) | W6: =MIN((IF('Your Debts'!$G$11=0,0,INDEX('Your Debts'!$B$5:$B$12,'Your Debts'!$G$11)))+V6,MAX(0,$C6-(E6+H6+K6+N6+Q6+T6))) | X6: =ROUND(MAX(0,(IF('Your Debts'!$G$11=0,0,INDEX('Your Debts'!$B$5:$B$12,'Your Debts'!$G$11)))+V6-W6),2) | Y6: =ROUND((IF('Your Debts'!$G$12=0,0,INDEX('Your Debts'!$B$5:$B$12,'Your Debts'!$G$12)))*(IF('Your Debts'!$G$12=0,0,INDEX('Your Debts'!$C$5:$C$12,'Your Debts'!$G$12)/12)),2) | Z6: =MIN((IF('Your Debts'!$G$12=0,0,INDEX('Your Debts'!$B$5:$B$12,'Your Debts'!$G$12)))+Y6,MAX(0,$C6-(E6+H6+K6+N6+Q6+T6+W6))) | AA6: =ROUND(MAX(0,(IF('Your Debts'!$G$12=0,0,INDEX('Your Debts'!$B$5:$B$12,'Your Debts'!$G$12)))+Y6-Z6),2) | AB6: =F6+I6+L6+O6+R6+U6+X6+AA6 | AC6: =0+D6+G6+J6+M6+P6+S6+V6+Y6
A7: 2 | B7: =EDATE('Your Debts'!$B$19,1) | C7: ='Your Debts'!$B$18 | D7: =ROUND((F6)*(IF('Your Debts'!$G$5=0,0,INDEX('Your Debts'!$C$5:$C$12,'Your Debts'!$G$5)/12)),2) | E7: =MIN((F6)+D7,MAX(0,$C7-(0))) | F7: =ROUND(MAX(0,(F6)+D7-E7),2) | G7: =ROUND((I6)*(IF('Your Debts'!$G$6=0,0,INDEX('Your Debts'!$C$5:$C$12,'Your Debts'!$G$6)/12)),2) | H7: =MIN((I6)+G7,MAX(0,$C7-(E7))) | I7: =ROUND(MAX(0,(I6)+G7-H7),2) | J7: =ROUND((L6)*(IF('Your Debts'!$G$7=0,0,INDEX('Your Debts'!$C$5:$C$12,'Your Debts'!$G$7)/12)),2) | K7: =MIN((L6)+J7,MAX(0,$C7-(E7+H7))) | L7: =ROUND(MAX(0,(L6)+J7-K7),2) | M7: =ROUND((O6)*(IF('Your Debts'!$G$8=0,0,INDEX('Your Debts'!$C$5:$C$12,'Your Debts'!$G$8)/12)),2) | N7: =MIN((O6)+M7,MAX(0,$C7-(E7+H7+K7))) | O7: =ROUND(MAX(0,(O6)+M7-N7),2) | P7: =ROUND((R6)*(IF('Your Debts'!$G$9=0,0,INDEX('Your Debts'!$C$5:$C$12,'Your Debts'!$G$9)/12)),2) | Q7: =MIN((R6)+P7,MAX(0,$C7-(E7+H7+K7+N7))) | R7: =ROUND(MAX(0,(R6)+P7-Q7),2) | S7: =ROUND((U6)*(IF('Your Debts'!$G$10=0,0,INDEX('Your Debts'!$C$5:$C$12,'Your Debts'!$G$10)/12)),2) | T7: =MIN((U6)+S7,MAX(0,$C7-(E7+H7+K7+N7+Q7))) | U7: =ROUND(MAX(0,(U6)+S7-T7),2) | V7: =ROUND((X6)*(IF('Your Debts'!$G$11=0,0,INDEX('Your Debts'!$C$5:$C$12,'Your Debts'!$G$11)/12)),2) | W7: =MIN((X6)+V7,MAX(0,$C7-(E7+H7+K7+N7+Q7+T7))) | X7: =ROUND(MAX(0,(X6)+V7-W7),2) | Y7: =ROUND((AA6)*(IF('Your Debts'!$G$12=0,0,INDEX('Your Debts'!$C$5:$C$12,'Your Debts'!$G$12)/12)),2) | Z7: =MIN((AA6)+Y7,MAX(0,$C7-(E7+H7+K7+N7+Q7+T7+W7))) | AA7: =ROUND(MAX(0,(AA6)+Y7-Z7),2) | AB7: =F7+I7+L7+O7+R7+U7+X7+AA7 | AC7: =AC6+D7+G7+J7+M7+P7+S7+V7+Y7
A8: 3 | B8: =EDATE('Your Debts'!$B$19,2) | C8: ='Your Debts'!$B$18 | D8: =ROUND((F7)*(IF('Your Debts'!$G$5=0,0,INDEX('Your Debts'!$C$5:$C$12,'Your Debts'!$G$5)/12)),2) | E8: =MIN((F7)+D8,MAX(0,$C8-(0))) | F8: =ROUND(MAX(0,(F7)+D8-E8),2) | G8: =ROUND((I7)*(IF('Your Debts'!$G$6=0,0,INDEX('Your Debts'!$C$5:$C$12,'Your Debts'!$G$6)/12)),2) | H8: =MIN((I7)+G8,MAX(0,$C8-(E8))) | I8: =ROUND(MAX(0,(I7)+G8-H8),2) | J8: =ROUND((L7)*(IF('Your Debts'!$G$7=0,0,INDEX('Your Debts'!$C$5:$C$12,'Your Debts'!$G$7)/12)),2) | K8: =MIN((L7)+J8,MAX(0,$C8-(E8+H8))) | L8: =ROUND(MAX(0,(L7)+J8-K8),2) | M8: =ROUND((O7)*(IF('Your Debts'!$G$8=0,0,INDEX('Your Debts'!$C$5:$C$12,'Your Debts'!$G$8)/12)),2) | N8: =MIN((O7)+M8,MAX(0,$C8-(E8+H8+K8))) | O8: =ROUND(MAX(0,(O7)+M8-N8),2) | P8: =ROUND((R7)*(IF('Your Debts'!$G$9=0,0,INDEX('Your Debts'!$C$5:$C$12,'Your Debts'!$G$9)/12)),2) | Q8: =MIN((R7)+P8,MAX(0,$C8-(E8+H8+K8+N8))) | R8: =ROUND(MAX(0,(R7)+P8-Q8),2) | S8: =ROUND((U7)*(IF('Your Debts'!$G$10=0,0,INDEX('Your Debts'!$C$5:$C$12,'Your Debts'!$G$10)/12)),2) | T8: =MIN((U7)+S8,MAX(0,$C8-(E8+H8+K8+N8+Q8))) | U8: =ROUND(MAX(0,(U7)+S8-T8),2) | V8: =ROUND((X7)*(IF('Your Debts'!$G$11=0,0,INDEX('Your Debts'!$C$5:$C$12,'Your Debts'!$G$11)/12)),2) | W8: =MIN((X7)+V8,MAX(0,$C8-(E8+H8+K8+N8+Q8+T8))) | X8: =ROUND(MAX(0,(X7)+V8-W8),2) | Y8: =ROUND((AA7)*(IF('Your Debts'!$G$12=0,0,INDEX('Your Debts'!$C$5:$C$12,'Your Debts'!$G$12)/12)),2) | Z8: =MIN((AA7)+Y8,MAX(0,$C8-(E8+H8+K8+N8+Q8+T8+W8))) | AA8: =ROUND(MAX(0,(AA7)+Y8-Z8),2) | AB8: =F8+I8+L8+O8+R8+U8+X8+AA8 | AC8: =AC7+D8+G8+J8+M8+P8+S8+V8+Y8
A9: 4 | B9: =EDATE('Your Debts'!$B$19,3) | C9: ='Your Debts'!$B$18 | D9: =ROUND((F8)*(IF('Your Debts'!$G$5=0,0,INDEX('Your Debts'!$C$5:$C$12,'Your Debts'!$G$5)/12)),2) | E9: =MIN((F8)+D9,MAX(0,$C9-(0))) | F9: =ROUND(MAX(0,(F8)+D9-E9),2) | G9: =ROUND((I8)*(IF('Your Debts'!$G$6=0,0,INDEX('Your Debts'!$C$5:$C$12,'Your Debts'!$G$6)/12)),2) | H9: =MIN((I8)+G9,MAX(0,$C9-(E9))) | I9: =ROUND(MAX(0,(I8)+G9-H9),2) | J9: =ROUND((L8)*(IF('Your Debts'!$G$7=0,0,INDEX('Your Debts'!$C$5:$C$12,'Your Debts'!$G$7)/12)),2) | K9: =MIN((L8)+J9,MAX(0,$C9-(E9+H9))) | L9: =ROUND(MAX(0,(L8)+J9-K9),2) | M9: =ROUND((O8)*(IF('Your Debts'!$G$8=0,0,INDEX('Your Debts'!$C$5:$C$12,'Your Debts'!$G$8)/12)),2) | N9: =MIN((O8)+M9,MAX(0,$C9-(E9+H9+K9))) | O9: =ROUND(MAX(0,(O8)+M9-N9),2) | P9: =ROUND((R8)*(IF('Your Debts'!$G$9=0,0,INDEX('Your Debts'!$C$5:$C$12,'Your Debts'!$G$9)/12)),2) | Q9: =MIN((R8)+P9,MAX(0,$C9-(E9+H9+K9+N9))) | R9: =ROUND(MAX(0,(R8)+P9-Q9),2) | S9: =ROUND((U8)*(IF('Your Debts'!$G$10=0,0,INDEX('Your Debts'!$C$5:$C$12,'Your Debts'!$G$10)/12)),2) | T9: =MIN((U8)+S9,MAX(0,$C9-(E9+H9+K9+N9+Q9))) | U9: =ROUND(MAX(0,(U8)+S9-T9),2) | V9: =ROUND((X8)*(IF('Your Debts'!$G$11=0,0,INDEX('Your Debts'!$C$5:$C$12,'Your Debts'!$G$11)/12)),2) | W9: =MIN((X8)+V9,MAX(0,$C9-(E9+H9+K9+N9+Q9+T9))) | X9: =ROUND(MAX(0,(X8)+V9-W9),2) | Y9: =ROUND((AA8)*(IF('Your Debts'!$G$12=0,0,INDEX('Your Debts'!$C$5:$C$12,'Your Debts'!$G$12)/12)),2) | Z9: =MIN((AA8)+Y9,MAX(0,$C9-(E9+H9+K9+N9+Q9+T9+W9))) | AA9: =ROUND(MAX(0,(AA8)+Y9-Z9),2) | AB9: =F9+I9+L9+O9+R9+U9+X9+AA9 | AC9: =AC8+D9+G9+J9+M9+P9+S9+V9+Y9
A10: 5 | B10: =EDATE('Your Debts'!$B$19,4) | C10: ='Your Debts'!$B$18 | D10: =ROUND((F9)*(IF('Your Debts'!$G$5=0,0,INDEX('Your Debts'!$C$5:$C$12,'Your Debts'!$G$5)/12)),2) | E10: =MIN((F9)+D10,MAX(0,$C10-(0))) | F10: =ROUND(MAX(0,(F9)+D10-E10),2) | G10: =ROUND((I9)*(IF('Your Debts'!$G$6=0,0,INDEX('Your Debts'!$C$5:$C$12,'Your Debts'!$G$6)/12)),2) | H10: =MIN((I9)+G10,MAX(0,$C10-(E10))) | I10: =ROUND(MAX(0,(I9)+G10-H10),2) | J10: =ROUND((L9)*(IF('Your Debts'!$G$7=0,0,INDEX('Your Debts'!$C$5:$C$12,'Your Debts'!$G$7)/12)),2) | K10: =MIN((L9)+J10,MAX(0,$C10-(E10+H10))) | L10: =ROUND(MAX(0,(L9)+J10-K10),2) | M10: =ROUND((O9)*(IF('Your Debts'!$G$8=0,0,INDEX('Your Debts'!$C$5:$C$12,'Your Debts'!$G$8)/12)),2) | N10: =MIN((O9)+M10,MAX(0,$C10-(E10+H10+K10))) | O10: =ROUND(MAX(0,(O9)+M10-N10),2) | P10: =ROUND((R9)*(IF('Your Debts'!$G$9=0,0,INDEX('Your Debts'!$C$5:$C$12,'Your Debts'!$G$9)/12)),2) | Q10: =MIN((R9)+P10,MAX(0,$C10-(E10+H10+K10+N10))) | R10: =ROUND(MAX(0,(R9)+P10-Q10),2) | S10: =ROUND((U9)*(IF('Your Debts'!$G$10=0,0,INDEX('Your Debts'!$C$5:$C$12,'Your Debts'!$G$10)/12)),2) | T10: =MIN((U9)+S10,MAX(0,$C10-(E10+H10+K10+N10+Q10))) | U10: =ROUND(MAX(0,(U9)+S10-T10),2) | V10: =ROUND((X9)*(IF('Your Debts'!$G$11=0,0,INDEX('Your Debts'!$C$5:$C$12,'Your Debts'!$G$11)/12)),2) | W10: =MIN((X9)+V10,MAX(0,$C10-(E10+H10+K10+N10+Q10+T10))) | X10: =ROUND(MAX(0,(X9)+V10-W10),2) | Y10: =ROUND((AA9)*(IF('Your Debts'!$G$12=0,0,INDEX('Your Debts'!$C$5:$C$12,'Your Debts'!$G$12)/12)),2) | Z10: =MIN((AA9)+Y10,MAX(0,$C10-(E10+H10+K10+N10+Q10+T10+W10))) | AA10: =ROUND(MAX(0,(AA9)+Y10-Z10),2) | AB10: =F10+I10+L10+O10+R10+U10+X10+AA10 | AC10: =AC9+D10+G10+J10+M10+P10+S10+V10+Y10
A11: 6 | B11: =EDATE('Your Debts'!$B$19,5) | C11: ='Your Debts'!$B$18 | D11: =ROUND((F10)*(IF('Your Debts'!$G$5=0,0,INDEX('Your Debts'!$C$5:$C$12,'Your Debts'!$G$5)/12)),2) | E11: =MIN((F10)+D11,MAX(0,$C11-(0))) | F11: =ROUND(MAX(0,(F10)+D11-E11),2) | G11: =ROUND((I10)*(IF('Your Debts'!$G$6=0,0,INDEX('Your Debts'!$C$5:$C$12,'Your Debts'!$G$6)/12)),2) | H11: =MIN((I10)+G11,MAX(0,$C11-(E11))) | I11: =ROUND(MAX(0,(I10)+G11-H11),2) | J11: =ROUND((L10)*(IF('Your Debts'!$G$7=0,0,INDEX('Your Debts'!$C$5:$C$12,'Your Debts'!$G$7)/12)),2) | K11: =MIN((L10)+J11,MAX(0,$C11-(E11+H11))) | L11: =ROUND(MAX(0,(L10)+J11-K11),2) | M11: =ROUND((O10)*(IF('Your Debts'!$G$8=0,0,INDEX('Your Debts'!$C$5:$C$12,'Your Debts'!$G$8)/12)),2) | N11: =MIN((O10)+M11,MAX(0,$C11-(E11+H11+K11))) | O11: =ROUND(MAX(0,(O10)+M11-N11),2) | P11: =ROUND((R10)*(IF('Your Debts'!$G$9=0,0,INDEX('Your Debts'!$C$5:$C$12,'Your Debts'!$G$9)/12)),2) | Q11: =MIN((R10)+P11,MAX(0,$C11-(E11+H11+K11+N11))) | R11: =ROUND(MAX(0,(R10)+P11-Q11),2) | S11: =ROUND((U10)*(IF('Your Debts'!$G$10=0,0,INDEX('Your Debts'!$C$5:$C$12,'Your Debts'!$G$10)/12)),2) | T11: =MIN((U10)+S11,MAX(0,$C11-(E11+H11+K11+N11+Q11))) | U11: =ROUND(MAX(0,(U10)+S11-T11),2) | V11: =ROUND((X10)*(IF('Your Debts'!$G$11=0,0,INDEX('Your Debts'!$C$5:$C$12,'Your Debts'!$G$11)/12)),2) | W11: =MIN((X10)+V11,MAX(0,$C11-(E11+H11+K11+N11+Q11+T11))) | X11: =ROUND(MAX(0,(X10)+V11-W11),2) | Y11: =ROUND((AA10)*(IF('Your Debts'!$G$12=0,0,INDEX('Your Debts'!$C$5:$C$12,'Your Debts'!$G$12)/12)),2) | Z11: =MIN((AA10)+Y11,MAX(0,$C11-(E11+H11+K11+N11+Q11+T11+W11))) | AA11: =ROUND(MAX(0,(AA10)+Y11-Z11),2) | AB11: =F11+I11+L11+O11+R11+U11+X11+AA11 | AC11: =AC10+D11+G11+J11+M11+P11+S11+V11+Y11
A12: 7 | B12: =EDATE('Your Debts'!$B$19,6) | C12: ='Your Debts'!$B$18 | D12: =ROUND((F11)*(IF('Your Debts'!$G$5=0,0,INDEX('Your Debts'!$C$5:$C$12,'Your Debts'!$G$5)/12)),2) | E12: =MIN((F11)+D12,MAX(0,$C12-(0))) | F12: =ROUND(MAX(0,(F11)+D12-E12),2) | G12: =ROUND((I11)*(IF('Your Debts'!$G$6=0,0,INDEX('Your Debts'!$C$5:$C$12,'Your Debts'!$G$6)/12)),2) | H12: =MIN((I11)+G12,MAX(0,$C12-(E12))) | I12: =ROUND(MAX(0,(I11)+G12-H12),2) | J12: =ROUND((L11)*(IF('Your Debts'!$G$7=0,0,INDEX('Your Debts'!$C$5:$C$12,'Your Debts'!$G$7)/12)),2) | K12: =MIN((L11)+J12,MAX(0,$C12-(E12+H12))) | L12: =ROUND(MAX(0,(L11)+J12-K12),2) | M12: =ROUND((O11)*(IF('Your Debts'!$G$8=0,0,INDEX('Your Debts'!$C$5:$C$12,'Your Debts'!$G$8)/12)),2) | N12: =MIN((O11)+M12,MAX(0,$C12-(E12+H12+K12))) | O12: =ROUND(MAX(0,(O11)+M12-N12),2) | P12: =ROUND((R11)*(IF('Your Debts'!$G$9=0,0,INDEX('Your Debts'!$C$5:$C$12,'Your Debts'!$G$9)/12)),2) | Q12: =MIN((R11)+P12,MAX(0,$C12-(E12+H12+K12+N12))) | R12: =ROUND(MAX(0,(R11)+P12-Q12),2) | S12: =ROUND((U11)*(IF('Your Debts'!$G$10=0,0,INDEX('Your Debts'!$C$5:$C$12,'Your Debts'!$G$10)/12)),2) | T12: =MIN((U11)+S12,MAX(0,$C12-(E12+H12+K12+N12+Q12))) | U12: =ROUND(MAX(0,(U11)+S12-T12),2) | V12: =ROUND((X11)*(IF('Your Debts'!$G$11=0,0,INDEX('Your Debts'!$C$5:$C$12,'Your Debts'!$G$11)/12)),2) | W12: =MIN((X11)+V12,MAX(0,$C12-(E12+H12+K12+N12+Q12+T12))) | X12: =ROUND(MAX(0,(X11)+V12-W12),2) | Y12: =ROUND((AA11)*(IF('Your Debts'!$G$12=0,0,INDEX('Your Debts'!$C$5:$C$12,'Your Debts'!$G$12)/12)),2) | Z12: =MIN((AA11)+Y12,MAX(0,$C12-(E12+H12+K12+N12+Q12+T12+W12))) | AA12: =ROUND(MAX(0,(AA11)+Y12-Z12),2) | AB12: =F12+I12+L12+O12+R12+U12+X12+AA12 | AC12: =AC11+D12+G12+J12+M12+P12+S12+V12+Y12
A13: 8 | B13: =EDATE('Your Debts'!$B$19,7) | C13: ='Your Debts'!$B$18 | D13: =ROUND((F12)*(IF('Your Debts'!$G$5=0,0,INDEX('Your Debts'!$C$5:$C$12,'Your Debts'!$G$5)/12)),2) | E13: =MIN((F12)+D13,MAX(0,$C13-(0))) | F13: =ROUND(MAX(0,(F12)+D13-E13),2) | G13: =ROUND((I12)*(IF('Your Debts'!$G$6=0,0,INDEX('Your Debts'!$C$5:$C$12,'Your Debts'!$G$6)/12)),2) | H13: =MIN((I12)+G13,MAX(0,$C13-(E13))) | I13: =ROUND(MAX(0,(I12)+G13-H13),2) | J13: =ROUND((L12)*(IF('Your Debts'!$G$7=0,0,INDEX('Your Debts'!$C$5:$C$12,'Your Debts'!$G$7)/12)),2) | K13: =MIN((L12)+J13,MAX(0,$C13-(E13+H13))) | L13: =ROUND(MAX(0,(L12)+J13-K13),2) | M13: =ROUND((O12)*(IF('Your Debts'!$G$8=0,0,INDEX('Your Debts'!$C$5:$C$12,'Your Debts'!$G$8)/12)),2) | N13: =MIN((O12)+M13,MAX(0,$C13-(E13+H13+K13))) | O13: =ROUND(MAX(0,(O12)+M13-N13),2) | P13: =ROUND((R12)*(IF('Your Debts'!$G$9=0,0,INDEX('Your Debts'!$C$5:$C$12,'Your Debts'!$G$9)/12)),2) | Q13: =MIN((R12)+P13,MAX(0,$C13-(E13+H13+K13+N13))) | R13: =ROUND(MAX(0,(R12)+P13-Q13),2) | S13: =ROUND((U12)*(IF('Your Debts'!$G$10=0,0,INDEX('Your Debts'!$C$5:$C$12,'Your Debts'!$G$10)/12)),2) | T13: =MIN((U12)+S13,MAX(0,$C13-(E13+H13+K13+N13+Q13))) | U13: =ROUND(MAX(0,(U12)+S13-T13),2) | V13: =ROUND((X12)*(IF('Your Debts'!$G$11=0,0,INDEX('Your Debts'!$C$5:$C$12,'Your Debts'!$G$11)/12)),2) | W13: =MIN((X12)+V13,MAX(0,$C13-(E13+H13+K13+N13+Q13+T13))) | X13: =ROUND(MAX(0,(X12)+V13-W13),2) | Y13: =ROUND((AA12)*(IF('Your Debts'!$G$12=0,0,INDEX('Your Debts'!$C$5:$C$12,'Your Debts'!$G$12)/12)),2) | Z13: =MIN((AA12)+Y13,MAX(0,$C13-(E13+H13+K13+N13+Q13+T13+W13))) | AA13: =ROUND(MAX(0,(AA12)+Y13-Z13),2) | AB13: =F13+I13+L13+O13+R13+U13+X13+AA13 | AC13: =AC12+D13+G13+J13+M13+P13+S13+V13+Y13
A14: 9 | B14: =EDATE('Your Debts'!$B$19,8) | C14: ='Your Debts'!$B$18 | D14: =ROUND((F13)*(IF('Your Debts'!$G$5=0,0,INDEX('Your Debts'!$C$5:$C$12,'Your Debts'!$G$5)/12)),2) | E14: =MIN((F13)+D14,MAX(0,$C14-(0))) | F14: =ROUND(MAX(0,(F13)+D14-E14),2) | G14: =ROUND((I13)*(IF('Your Debts'!$G$6=0,0,INDEX('Your Debts'!$C$5:$C$12,'Your Debts'!$G$6)/12)),2) | H14: =MIN((I13)+G14,MAX(0,$C14-(E14))) | I14: =ROUND(MAX(0,(I13)+G14-H14),2) | J14: =ROUND((L13)*(IF('Your Debts'!$G$7=0,0,INDEX('Your Debts'!$C$5:$C$12,'Your Debts'!$G$7)/12)),2) | K14: =MIN((L13)+J14,MAX(0,$C14-(E14+H14))) | L14: =ROUND(MAX(0,(L13)+J14-K14),2) | M14: =ROUND((O13)*(IF('Your Debts'!$G$8=0,0,INDEX('Your Debts'!$C$5:$C$12,'Your Debts'!$G$8)/12)),2) | N14: =MIN((O13)+M14,MAX(0,$C14-(E14+H14+K14))) | O14: =ROUND(MAX(0,(O13)+M14-N14),2) | P14: =ROUND((R13)*(IF('Your Debts'!$G$9=0,0,INDEX('Your Debts'!$C$5:$C$12,'Your Debts'!$G$9)/12)),2) | Q14: =MIN((R13)+P14,MAX(0,$C14-(E14+H14+K14+N14))) | R14: =ROUND(MAX(0,(R13)+P14-Q14),2) | S14: =ROUND((U13)*(IF('Your Debts'!$G$10=0,0,INDEX('Your Debts'!$C$5:$C$12,'Your Debts'!$G$10)/12)),2) | T14: =MIN((U13)+S14,MAX(0,$C14-(E14+H14+K14+N14+Q14))) | U14: =ROUND(MAX(0,(U13)+S14-T14),2) | V14: =ROUND((X13)*(IF('Your Debts'!$G$11=0,0,INDEX('Your Debts'!$C$5:$C$12,'Your Debts'!$G$11)/12)),2) | W14: =MIN((X13)+V14,MAX(0,$C14-(E14+H14+K14+N14+Q14+T14))) | X14: =ROUND(MAX(0,(X13)+V14-W14),2) | Y14: =ROUND((AA13)*(IF('Your Debts'!$G$12=0,0,INDEX('Your Debts'!$C$5:$C$12,'Your Debts'!$G$12)/12)),2) | Z14: =MIN((AA13)+Y14,MAX(0,$C14-(E14+H14+K14+N14+Q14+T14+W14))) | AA14: =ROUND(MAX(0,(AA13)+Y14-Z14),2) | AB14: =F14+I14+L14+O14+R14+U14+X14+AA14 | AC14: =AC13+D14+G14+J14+M14+P14+S14+V14+Y14
A15: 10 | B15: =EDATE('Your Debts'!$B$19,9) | C15: ='Your Debts'!$B$18 | D15: =ROUND((F14)*(IF('Your Debts'!$G$5=0,0,INDEX('Your Debts'!$C$5:$C$12,'Your Debts'!$G$5)/12)),2) | E15: =MIN((F14)+D15,MAX(0,$C15-(0))) | F15: =ROUND(MAX(0,(F14)+D15-E15),2) | G15: =ROUND((I14)*(IF('Your Debts'!$G$6=0,0,INDEX('Your Debts'!$C$5:$C$12,'Your Debts'!$G$6)/12)),2) | H15: =MIN((I14)+G15,MAX(0,$C15-(E15))) | I15: =ROUND(MAX(0,(I14)+G15-H15),2) | J15: =ROUND((L14)*(IF('Your Debts'!$G$7=0,0,INDEX('Your Debts'!$C$5:$C$12,'Your Debts'!$G$7)/12)),2) | K15: =MIN((L14)+J15,MAX(0,$C15-(E15+H15))) | L15: =ROUND(MAX(0,(L14)+J15-K15),2) | M15: =ROUND((O14)*(IF('Your Debts'!$G$8=0,0,INDEX('Your Debts'!$C$5:$C$12,'Your Debts'!$G$8)/12)),2) | N15: =MIN((O14)+M15,MAX(0,$C15-(E15+H15+K15))) | O15: =ROUND(MAX(0,(O14)+M15-N15),2) | P15: =ROUND((R14)*(IF('Your Debts'!$G$9=0,0,INDEX('Your Debts'!$C$5:$C$12,'Your Debts'!$G$9)/12)),2) | Q15: =MIN((R14)+P15,MAX(0,$C15-(E15+H15+K15+N15))) | R15: =ROUND(MAX(0,(R14)+P15-Q15),2) | S15: =ROUND((U14)*(IF('Your Debts'!$G$10=0,0,INDEX('Your Debts'!$C$5:$C$12,'Your Debts'!$G$10)/12)),2) | T15: =MIN((U14)+S15,MAX(0,$C15-(E15+H15+K15+N15+Q15))) | U15: =ROUND(MAX(0,(U14)+S15-T15),2) | V15: =ROUND((X14)*(IF('Your Debts'!$G$11=0,0,INDEX('Your Debts'!$C$5:$C$12,'Your Debts'!$G$11)/12)),2) | W15: =MIN((X14)+V15,MAX(0,$C15-(E15+H15+K15+N15+Q15+T15))) | X15: =ROUND(MAX(0,(X14)+V15-W15),2) | Y15: =ROUND((AA14)*(IF('Your Debts'!$G$12=0,0,INDEX('Your Debts'!$C$5:$C$12,'Your Debts'!$G$12)/12)),2) | Z15: =MIN((AA14)+Y15,MAX(0,$C15-(E15+H15+K15+N15+Q15+T15+W15))) | AA15: =ROUND(MAX(0,(AA14)+Y15-Z15),2) | AB15: =F15+I15+L15+O15+R15+U15+X15+AA15 | AC15: =AC14+D15+G15+J15+M15+P15+S15+V15+Y15
A16: 11 | B16: =EDATE('Your Debts'!$B$19,10) | C16: ='Your Debts'!$B$18 | D16: =ROUND((F15)*(IF('Your Debts'!$G$5=0,0,INDEX('Your Debts'!$C$5:$C$12,'Your Debts'!$G$5)/12)),2) | E16: =MIN((F15)+D16,MAX(0,$C16-(0))) | F16: =ROUND(MAX(0,(F15)+D16-E16),2) | G16: =ROUND((I15)*(IF('Your Debts'!$G$6=0,0,INDEX('Your Debts'!$C$5:$C$12,'Your Debts'!$G$6)/12)),2) | H16: =MIN((I15)+G16,MAX(0,$C16-(E16))) | I16: =ROUND(MAX(0,(I15)+G16-H16),2) | J16: =ROUND((L15)*(IF('Your Debts'!$G$7=0,0,INDEX('Your Debts'!$C$5:$C$12,'Your Debts'!$G$7)/12)),2) | K16: =MIN((L15)+J16,MAX(0,$C16-(E16+H16))) | L16: =ROUND(MAX(0,(L15)+J16-K16),2) | M16: =ROUND((O15)*(IF('Your Debts'!$G$8=0,0,INDEX('Your Debts'!$C$5:$C$12,'Your Debts'!$G$8)/12)),2) | N16: =MIN((O15)+M16,MAX(0,$C16-(E16+H16+K16))) | O16: =ROUND(MAX(0,(O15)+M16-N16),2) | P16: =ROUND((R15)*(IF('Your Debts'!$G$9=0,0,INDEX('Your Debts'!$C$5:$C$12,'Your Debts'!$G$9)/12)),2) | Q16: =MIN((R15)+P16,MAX(0,$C16-(E16+H16+K16+N16))) | R16: =ROUND(MAX(0,(R15)+P16-Q16),2) | S16: =ROUND((U15)*(IF('Your Debts'!$G$10=0,0,INDEX('Your Debts'!$C$5:$C$12,'Your Debts'!$G$10)/12)),2) | T16: =MIN((U15)+S16,MAX(0,$C16-(E16+H16+K16+N16+Q16))) | U16: =ROUND(MAX(0,(U15)+S16-T16),2) | V16: =ROUND((X15)*(IF('Your Debts'!$G$11=0,0,INDEX('Your Debts'!$C$5:$C$12,'Your Debts'!$G$11)/12)),2) | W16: =MIN((X15)+V16,MAX(0,$C16-(E16+H16+K16+N16+Q16+T16))) | X16: =ROUND(MAX(0,(X15)+V16-W16),2) | Y16: =ROUND((AA15)*(IF('Your Debts'!$G$12=0,0,INDEX('Your Debts'!$C$5:$C$12,'Your Debts'!$G$12)/12)),2) | Z16: =MIN((AA15)+Y16,MAX(0,$C16-(E16+H16+K16+N16+Q16+T16+W16))) | AA16: =ROUND(MAX(0,(AA15)+Y16-Z16),2) | AB16: =F16+I16+L16+O16+R16+U16+X16+AA16 | AC16: =AC15+D16+G16+J16+M16+P16+S16+V16+Y16
A17: 12 | B17: =EDATE('Your Debts'!$B$19,11) | C17: ='Your Debts'!$B$18 | D17: =ROUND((F16)*(IF('Your Debts'!$G$5=0,0,INDEX('Your Debts'!$C$5:$C$12,'Your Debts'!$G$5)/12)),2) | E17: =MIN((F16)+D17,MAX(0,$C17-(0))) | F17: =ROUND(MAX(0,(F16)+D17-E17),2) | G17: =ROUND((I16)*(IF('Your Debts'!$G$6=0,0,INDEX('Your Debts'!$C$5:$C$12,'Your Debts'!$G$6)/12)),2) | H17: =MIN((I16)+G17,MAX(0,$C17-(E17))) | I17: =ROUND(MAX(0,(I16)+G17-H17),2) | J17: =ROUND((L16)*(IF('Your Debts'!$G$7=0,0,INDEX('Your Debts'!$C$5:$C$12,'Your Debts'!$G$7)/12)),2) | K17: =MIN((L16)+J17,MAX(0,$C17-(E17+H17))) | L17: =ROUND(MAX(0,(L16)+J17-K17),2) | M17: =ROUND((O16)*(IF('Your Debts'!$G$8=0,0,INDEX('Your Debts'!$C$5:$C$12,'Your Debts'!$G$8)/12)),2) | N17: =MIN((O16)+M17,MAX(0,$C17-(E17+H17+K17))) | O17: =ROUND(MAX(0,(O16)+M17-N17),2) | P17: =ROUND((R16)*(IF('Your Debts'!$G$9=0,0,INDEX('Your Debts'!$C$5:$C$12,'Your Debts'!$G$9)/12)),2) | Q17: =MIN((R16)+P17,MAX(0,$C17-(E17+H17+K17+N17))) | R17: =ROUND(MAX(0,(R16)+P17-Q17),2) | S17: =ROUND((U16)*(IF('Your Debts'!$G$10=0,0,INDEX('Your Debts'!$C$5:$C$12,'Your Debts'!$G$10)/12)),2) | T17: =MIN((U16)+S17,MAX(0,$C17-(E17+H17+K17+N17+Q17))) | U17: =ROUND(MAX(0,(U16)+S17-T17),2) | V17: =ROUND((X16)*(IF('Your Debts'!$G$11=0,0,INDEX('Your Debts'!$C$5:$C$12,'Your Debts'!$G$11)/12)),2) | W17: =MIN((X16)+V17,MAX(0,$C17-(E17+H17+K17+N17+Q17+T17))) | X17: =ROUND(MAX(0,(X16)+V17-W17),2) | Y17: =ROUND((AA16)*(IF('Your Debts'!$G$12=0,0,INDEX('Your Debts'!$C$5:$C$12,'Your Debts'!$G$12)/12)),2) | Z17: =MIN((AA16)+Y17,MAX(0,$C17-(E17+H17+K17+N17+Q17+T17+W17))) | AA17: =ROUND(MAX(0,(AA16)+Y17-Z17),2) | AB17: =F17+I17+L17+O17+R17+U17+X17+AA17 | AC17: =AC16+D17+G17+J17+M17+P17+S17+V17+Y17
A18: 13 | B18: =EDATE('Your Debts'!$B$19,12) | C18: ='Your Debts'!$B$18 | D18: =ROUND((F17)*(IF('Your Debts'!$G$5=0,0,INDEX('Your Debts'!$C$5:$C$12,'Your Debts'!$G$5)/12)),2) | E18: =MIN((F17)+D18,MAX(0,$C18-(0))) | F18: =ROUND(MAX(0,(F17)+D18-E18),2) | G18: =ROUND((I17)*(IF('Your Debts'!$G$6=0,0,INDEX('Your Debts'!$C$5:$C$12,'Your Debts'!$G$6)/12)),2) | H18: =MIN((I17)+G18,MAX(0,$C18-(E18))) | I18: =ROUND(MAX(0,(I17)+G18-H18),2) | J18: =ROUND((L17)*(IF('Your Debts'!$G$7=0,0,INDEX('Your Debts'!$C$5:$C$12,'Your Debts'!$G$7)/12)),2) | K18: =MIN((L17)+J18,MAX(0,$C18-(E18+H18))) | L18: =ROUND(MAX(0,(L17)+J18-K18),2) | M18: =ROUND((O17)*(IF('Your Debts'!$G$8=0,0,INDEX('Your Debts'!$C$5:$C$12,'Your Debts'!$G$8)/12)),2) | N18: =MIN((O17)+M18,MAX(0,$C18-(E18+H18+K18))) | O18: =ROUND(MAX(0,(O17)+M18-N18),2) | P18: =ROUND((R17)*(IF('Your Debts'!$G$9=0,0,INDEX('Your Debts'!$C$5:$C$12,'Your Debts'!$G$9)/12)),2) | Q18: =MIN((R17)+P18,MAX(0,$C18-(E18+H18+K18+N18))) | R18: =ROUND(MAX(0,(R17)+P18-Q18),2) | S18: =ROUND((U17)*(IF('Your Debts'!$G$10=0,0,INDEX('Your Debts'!$C$5:$C$12,'Your Debts'!$G$10)/12)),2) | T18: =MIN((U17)+S18,MAX(0,$C18-(E18+H18+K18+N18+Q18))) | U18: =ROUND(MAX(0,(U17)+S18-T18),2) | V18: =ROUND((X17)*(IF('Your Debts'!$G$11=0,0,INDEX('Your Debts'!$C$5:$C$12,'Your Debts'!$G$11)/12)),2) | W18: =MIN((X17)+V18,MAX(0,$C18-(E18+H18+K18+N18+Q18+T18))) | X18: =ROUND(MAX(0,(X17)+V18-W18),2) | Y18: =ROUND((AA17)*(IF('Your Debts'!$G$12=0,0,INDEX('Your Debts'!$C$5:$C$12,'Your Debts'!$G$12)/12)),2) | Z18: =MIN((AA17)+Y18,MAX(0,$C18-(E18+H18+K18+N18+Q18+T18+W18))) | AA18: =ROUND(MAX(0,(AA17)+Y18-Z18),2) | AB18: =F18+I18+L18+O18+R18+U18+X18+AA18 | AC18: =AC17+D18+G18+J18+M18+P18+S18+V18+Y18
A19: 14 | B19: =EDATE('Your Debts'!$B$19,13) | C19: ='Your Debts'!$B$18 | D19: =ROUND((F18)*(IF('Your Debts'!$G$5=0,0,INDEX('Your Debts'!$C$5:$C$12,'Your Debts'!$G$5)/12)),2) | E19: =MIN((F18)+D19,MAX(0,$C19-(0))) | F19: =ROUND(MAX(0,(F18)+D19-E19),2) | G19: =ROUND((I18)*(IF('Your Debts'!$G$6=0,0,INDEX('Your Debts'!$C$5:$C$12,'Your Debts'!$G$6)/12)),2) | H19: =MIN((I18)+G19,MAX(0,$C19-(E19))) | I19: =ROUND(MAX(0,(I18)+G19-H19),2) | J19: =ROUND((L18)*(IF('Your Debts'!$G$7=0,0,INDEX('Your Debts'!$C$5:$C$12,'Your Debts'!$G$7)/12)),2) | K19: =MIN((L18)+J19,MAX(0,$C19-(E19+H19))) | L19: =ROUND(MAX(0,(L18)+J19-K19),2) | M19: =ROUND((O18)*(IF('Your Debts'!$G$8=0,0,INDEX('Your Debts'!$C$5:$C$12,'Your Debts'!$G$8)/12)),2) | N19: =MIN((O18)+M19,MAX(0,$C19-(E19+H19+K19))) | O19: =ROUND(MAX(0,(O18)+M19-N19),2) | P19: =ROUND((R18)*(IF('Your Debts'!$G$9=0,0,INDEX('Your Debts'!$C$5:$C$12,'Your Debts'!$G$9)/12)),2) | Q19: =MIN((R18)+P19,MAX(0,$C19-(E19+H19+K19+N19))) | R19: =ROUND(MAX(0,(R18)+P19-Q19),2) | S19: =ROUND((U18)*(IF('Your Debts'!$G$10=0,0,INDEX('Your Debts'!$C$5:$C$12,'Your Debts'!$G$10)/12)),2) | T19: =MIN((U18)+S19,MAX(0,$C19-(E19+H19+K19+N19+Q19))) | U19: =ROUND(MAX(0,(U18)+S19-T19),2) | V19: =ROUND((X18)*(IF('Your Debts'!$G$11=0,0,INDEX('Your Debts'!$C$5:$C$12,'Your Debts'!$G$11)/12)),2) | W19: =MIN((X18)+V19,MAX(0,$C19-(E19+H19+K19+N19+Q19+T19))) | X19: =ROUND(MAX(0,(X18)+V19-W19),2) | Y19: =ROUND((AA18)*(IF('Your Debts'!$G$12=0,0,INDEX('Your Debts'!$C$5:$C$12,'Your Debts'!$G$12)/12)),2) | Z19: =MIN((AA18)+Y19,MAX(0,$C19-(E19+H19+K19+N19+Q19+T19+W19))) | AA19: =ROUND(MAX(0,(AA18)+Y19-Z19),2) | AB19: =F19+I19+L19+O19+R19+U19+X19+AA19 | AC19: =AC18+D19+G19+J19+M19+P19+S19+V19+Y19
A20: 15 | B20: =EDATE('Your Debts'!$B$19,14) | C20: ='Your Debts'!$B$18 | D20: =ROUND((F19)*(IF('Your Debts'!$G$5=0,0,INDEX('Your Debts'!$C$5:$C$12,'Your Debts'!$G$5)/12)),2) | E20: =MIN((F19)+D20,MAX(0,$C20-(0))) | F20: =ROUND(MAX(0,(F19)+D20-E20),2) | G20: =ROUND((I19)*(IF('Your Debts'!$G$6=0,0,INDEX('Your Debts'!$C$5:$C$12,'Your Debts'!$G$6)/12)),2) | H20: =MIN((I19)+G20,MAX(0,$C20-(E20))) | I20: =ROUND(MAX(0,(I19)+G20-H20),2) | J20: =ROUND((L19)*(IF('Your Debts'!$G$7=0,0,INDEX('Your Debts'!$C$5:$C$12,'Your Debts'!$G$7)/12)),2) | K20: =MIN((L19)+J20,MAX(0,$C20-(E20+H20))) | L20: =ROUND(MAX(0,(L19)+J20-K20),2) | M20: =ROUND((O19)*(IF('Your Debts'!$G$8=0,0,INDEX('Your Debts'!$C$5:$C$12,'Your Debts'!$G$8)/12)),2) | N20: =MIN((O19)+M20,MAX(0,$C20-(E20+H20+K20))) | O20: =ROUND(MAX(0,(O19)+M20-N20),2) | P20: =ROUND((R19)*(IF('Your Debts'!$G$9=0,0,INDEX('Your Debts'!$C$5:$C$12,'Your Debts'!$G$9)/12)),2) | Q20: =MIN((R19)+P20,MAX(0,$C20-(E20+H20+K20+N20))) | R20: =ROUND(MAX(0,(R19)+P20-Q20),2) | S20: =ROUND((U19)*(IF('Your Debts'!$G$10=0,0,INDEX('Your Debts'!$C$5:$C$12,'Your Debts'!$G$10)/12)),2) | T20: =MIN((U19)+S20,MAX(0,$C20-(E20+H20+K20+N20+Q20))) | U20: =ROUND(MAX(0,(U19)+S20-T20),2) | V20: =ROUND((X19)*(IF('Your Debts'!$G$11=0,0,INDEX('Your Debts'!$C$5:$C$12,'Your Debts'!$G$11)/12)),2) | W20: =MIN((X19)+V20,MAX(0,$C20-(E20+H20+K20+N20+Q20+T20))) | X20: =ROUND(MAX(0,(X19)+V20-W20),2) | Y20: =ROUND((AA19)*(IF('Your Debts'!$G$12=0,0,INDEX('Your Debts'!$C$5:$C$12,'Your Debts'!$G$12)/12)),2) | Z20: =MIN((AA19)+Y20,MAX(0,$C20-(E20+H20+K20+N20+Q20+T20+W20))) | AA20: =ROUND(MAX(0,(AA19)+Y20-Z20),2) | AB20: =F20+I20+L20+O20+R20+U20+X20+AA20 | AC20: =AC19+D20+G20+J20+M20+P20+S20+V20+Y20
A21: 16 | B21: =EDATE('Your Debts'!$B$19,15) | C21: ='Your Debts'!$B$18 | D21: =ROUND((F20)*(IF('Your Debts'!$G$5=0,0,INDEX('Your Debts'!$C$5:$C$12,'Your Debts'!$G$5)/12)),2) | E21: =MIN((F20)+D21,MAX(0,$C21-(0))) | F21: =ROUND(MAX(0,(F20)+D21-E21),2) | G21: =ROUND((I20)*(IF('Your Debts'!$G$6=0,0,INDEX('Your Debts'!$C$5:$C$12,'Your Debts'!$G$6)/12)),2) | H21: =MIN((I20)+G21,MAX(0,$C21-(E21))) | I21: =ROUND(MAX(0,(I20)+G21-H21),2) | J21: =ROUND((L20)*(IF('Your Debts'!$G$7=0,0,INDEX('Your Debts'!$C$5:$C$12,'Your Debts'!$G$7)/12)),2) | K21: =MIN((L20)+J21,MAX(0,$C21-(E21+H21))) | L21: =ROUND(MAX(0,(L20)+J21-K21),2) | M21: =ROUND((O20)*(IF('Your Debts'!$G$8=0,0,INDEX('Your Debts'!$C$5:$C$12,'Your Debts'!$G$8)/12)),2) | N21: =MIN((O20)+M21,MAX(0,$C21-(E21+H21+K21))) | O21: =ROUND(MAX(0,(O20)+M21-N21),2) | P21: =ROUND((R20)*(IF('Your Debts'!$G$9=0,0,INDEX('Your Debts'!$C$5:$C$12,'Your Debts'!$G$9)/12)),2) | Q21: =MIN((R20)+P21,MAX(0,$C21-(E21+H21+K21+N21))) | R21: =ROUND(MAX(0,(R20)+P21-Q21),2) | S21: =ROUND((U20)*(IF('Your Debts'!$G$10=0,0,INDEX('Your Debts'!$C$5:$C$12,'Your Debts'!$G$10)/12)),2) | T21: =MIN((U20)+S21,MAX(0,$C21-(E21+H21+K21+N21+Q21))) | U21: =ROUND(MAX(0,(U20)+S21-T21),2) | V21: =ROUND((X20)*(IF('Your Debts'!$G$11=0,0,INDEX('Your Debts'!$C$5:$C$12,'Your Debts'!$G$11)/12)),2) | W21: =MIN((X20)+V21,MAX(0,$C21-(E21+H21+K21+N21+Q21+T21))) | X21: =ROUND(MAX(0,(X20)+V21-W21),2) | Y21: =ROUND((AA20)*(IF('Your Debts'!$G$12=0,0,INDEX('Your Debts'!$C$5:$C$12,'Your Debts'!$G$12)/12)),2) | Z21: =MIN((AA20)+Y21,MAX(0,$C21-(E21+H21+K21+N21+Q21+T21+W21))) | AA21: =ROUND(MAX(0,(AA20)+Y21-Z21),2) | AB21: =F21+I21+L21+O21+R21+U21+X21+AA21 | AC21: =AC20+D21+G21+J21+M21+P21+S21+V21+Y21
A22: 17 | B22: =EDATE('Your Debts'!$B$19,16) | C22: ='Your Debts'!$B$18 | D22: =ROUND((F21)*(IF('Your Debts'!$G$5=0,0,INDEX('Your Debts'!$C$5:$C$12,'Your Debts'!$G$5)/12)),2) | E22: =MIN((F21)+D22,MAX(0,$C22-(0))) | F22: =ROUND(MAX(0,(F21)+D22-E22),2) | G22: =ROUND((I21)*(IF('Your Debts'!$G$6=0,0,INDEX('Your Debts'!$C$5:$C$12,'Your Debts'!$G$6)/12)),2) | H22: =MIN((I21)+G22,MAX(0,$C22-(E22))) | I22: =ROUND(MAX(0,(I21)+G22-H22),2) | J22: =ROUND((L21)*(IF('Your Debts'!$G$7=0,0,INDEX('Your Debts'!$C$5:$C$12,'Your Debts'!$G$7)/12)),2) | K22: =MIN((L21)+J22,MAX(0,$C22-(E22+H22))) | L22: =ROUND(MAX(0,(L21)+J22-K22),2) | M22: =ROUND((O21)*(IF('Your Debts'!$G$8=0,0,INDEX('Your Debts'!$C$5:$C$12,'Your Debts'!$G$8)/12)),2) | N22: =MIN((O21)+M22,MAX(0,$C22-(E22+H22+K22))) | O22: =ROUND(MAX(0,(O21)+M22-N22),2) | P22: =ROUND((R21)*(IF('Your Debts'!$G$9=0,0,INDEX('Your Debts'!$C$5:$C$12,'Your Debts'!$G$9)/12)),2) | Q22: =MIN((R21)+P22,MAX(0,$C22-(E22+H22+K22+N22))) | R22: =ROUND(MAX(0,(R21)+P22-Q22),2) | S22: =ROUND((U21)*(IF('Your Debts'!$G$10=0,0,INDEX('Your Debts'!$C$5:$C$12,'Your Debts'!$G$10)/12)),2) | T22: =MIN((U21)+S22,MAX(0,$C22-(E22+H22+K22+N22+Q22))) | U22: =ROUND(MAX(0,(U21)+S22-T22),2) | V22: =ROUND((X21)*(IF('Your Debts'!$G$11=0,0,INDEX('Your Debts'!$C$5:$C$12,'Your Debts'!$G$11)/12)),2) | W22: =MIN((X21)+V22,MAX(0,$C22-(E22+H22+K22+N22+Q22+T22))) | X22: =ROUND(MAX(0,(X21)+V22-W22),2) | Y22: =ROUND((AA21)*(IF('Your Debts'!$G$12=0,0,INDEX('Your Debts'!$C$5:$C$12,'Your Debts'!$G$12)/12)),2) | Z22: =MIN((AA21)+Y22,MAX(0,$C22-(E22+H22+K22+N22+Q22+T22+W22))) | AA22: =ROUND(MAX(0,(AA21)+Y22-Z22),2) | AB22: =F22+I22+L22+O22+R22+U22+X22+AA22 | AC22: =AC21+D22+G22+J22+M22+P22+S22+V22+Y22
A23: 18 | B23: =EDATE('Your Debts'!$B$19,17) | C23: ='Your Debts'!$B$18 | D23: =ROUND((F22)*(IF('Your Debts'!$G$5=0,0,INDEX('Your Debts'!$C$5:$C$12,'Your Debts'!$G$5)/12)),2) | E23: =MIN((F22)+D23,MAX(0,$C23-(0))) | F23: =ROUND(MAX(0,(F22)+D23-E23),2) | G23: =ROUND((I22)*(IF('Your Debts'!$G$6=0,0,INDEX('Your Debts'!$C$5:$C$12,'Your Debts'!$G$6)/12)),2) | H23: =MIN((I22)+G23,MAX(0,$C23-(E23))) | I23: =ROUND(MAX(0,(I22)+G23-H23),2) | J23: =ROUND((L22)*(IF('Your Debts'!$G$7=0,0,INDEX('Your Debts'!$C$5:$C$12,'Your Debts'!$G$7)/12)),2) | K23: =MIN((L22)+J23,MAX(0,$C23-(E23+H23))) | L23: =ROUND(MAX(0,(L22)+J23-K23),2) | M23: =ROUND((O22)*(IF('Your Debts'!$G$8=0,0,INDEX('Your Debts'!$C$5:$C$12,'Your Debts'!$G$8)/12)),2) | N23: =MIN((O22)+M23,MAX(0,$C23-(E23+H23+K23))) | O23: =ROUND(MAX(0,(O22)+M23-N23),2) | P23: =ROUND((R22)*(IF('Your Debts'!$G$9=0,0,INDEX('Your Debts'!$C$5:$C$12,'Your Debts'!$G$9)/12)),2) | Q23: =MIN((R22)+P23,MAX(0,$C23-(E23+H23+K23+N23))) | R23: =ROUND(MAX(0,(R22)+P23-Q23),2) | S23: =ROUND((U22)*(IF('Your Debts'!$G$10=0,0,INDEX('Your Debts'!$C$5:$C$12,'Your Debts'!$G$10)/12)),2) | T23: =MIN((U22)+S23,MAX(0,$C23-(E23+H23+K23+N23+Q23))) | U23: =ROUND(MAX(0,(U22)+S23-T23),2) | V23: =ROUND((X22)*(IF('Your Debts'!$G$11=0,0,INDEX('Your Debts'!$C$5:$C$12,'Your Debts'!$G$11)/12)),2) | W23: =MIN((X22)+V23,MAX(0,$C23-(E23+H23+K23+N23+Q23+T23))) | X23: =ROUND(MAX(0,(X22)+V23-W23),2) | Y23: =ROUND((AA22)*(IF('Your Debts'!$G$12=0,0,INDEX('Your Debts'!$C$5:$C$12,'Your Debts'!$G$12)/12)),2) | Z23: =MIN((AA22)+Y23,MAX(0,$C23-(E23+H23+K23+N23+Q23+T23+W23))) | AA23: =ROUND(MAX(0,(AA22)+Y23-Z23),2) | AB23: =F23+I23+L23+O23+R23+U23+X23+AA23 | AC23: =AC22+D23+G23+J23+M23+P23+S23+V23+Y23
A24: 19 | B24: =EDATE('Your Debts'!$B$19,18) | C24: ='Your Debts'!$B$18 | D24: =ROUND((F23)*(IF('Your Debts'!$G$5=0,0,INDEX('Your Debts'!$C$5:$C$12,'Your Debts'!$G$5)/12)),2) | E24: =MIN((F23)+D24,MAX(0,$C24-(0))) | F24: =ROUND(MAX(0,(F23)+D24-E24),2) | G24: =ROUND((I23)*(IF('Your Debts'!$G$6=0,0,INDEX('Your Debts'!$C$5:$C$12,'Your Debts'!$G$6)/12)),2) | H24: =MIN((I23)+G24,MAX(0,$C24-(E24))) | I24: =ROUND(MAX(0,(I23)+G24-H24),2) | J24: =ROUND((L23)*(IF('Your Debts'!$G$7=0,0,INDEX('Your Debts'!$C$5:$C$12,'Your Debts'!$G$7)/12)),2) | K24: =MIN((L23)+J24,MAX(0,$C24-(E24+H24))) | L24: =ROUND(MAX(0,(L23)+J24-K24),2) | M24: =ROUND((O23)*(IF('Your Debts'!$G$8=0,0,INDEX('Your Debts'!$C$5:$C$12,'Your Debts'!$G$8)/12)),2) | N24: =MIN((O23)+M24,MAX(0,$C24-(E24+H24+K24))) | O24: =ROUND(MAX(0,(O23)+M24-N24),2) | P24: =ROUND((R23)*(IF('Your Debts'!$G$9=0,0,INDEX('Your Debts'!$C$5:$C$12,'Your Debts'!$G$9)/12)),2) | Q24: =MIN((R23)+P24,MAX(0,$C24-(E24+H24+K24+N24))) | R24: =ROUND(MAX(0,(R23)+P24-Q24),2) | S24: =ROUND((U23)*(IF('Your Debts'!$G$10=0,0,INDEX('Your Debts'!$C$5:$C$12,'Your Debts'!$G$10)/12)),2) | T24: =MIN((U23)+S24,MAX(0,$C24-(E24+H24+K24+N24+Q24))) | U24: =ROUND(MAX(0,(U23)+S24-T24),2) | V24: =ROUND((X23)*(IF('Your Debts'!$G$11=0,0,INDEX('Your Debts'!$C$5:$C$12,'Your Debts'!$G$11)/12)),2) | W24: =MIN((X23)+V24,MAX(0,$C24-(E24+H24+K24+N24+Q24+T24))) | X24: =ROUND(MAX(0,(X23)+V24-W24),2) | Y24: =ROUND((AA23)*(IF('Your Debts'!$G$12=0,0,INDEX('Your Debts'!$C$5:$C$12,'Your Debts'!$G$12)/12)),2) | Z24: =MIN((AA23)+Y24,MAX(0,$C24-(E24+H24+K24+N24+Q24+T24+W24))) | AA24: =ROUND(MAX(0,(AA23)+Y24-Z24),2) | AB24: =F24+I24+L24+O24+R24+U24+X24+AA24 | AC24: =AC23+D24+G24+J24+M24+P24+S24+V24+Y24
A25: 20 | B25: =EDATE('Your Debts'!$B$19,19) | C25: ='Your Debts'!$B$18 | D25: =ROUND((F24)*(IF('Your Debts'!$G$5=0,0,INDEX('Your Debts'!$C$5:$C$12,'Your Debts'!$G$5)/12)),2) | E25: =MIN((F24)+D25,MAX(0,$C25-(0))) | F25: =ROUND(MAX(0,(F24)+D25-E25),2) | G25: =ROUND((I24)*(IF('Your Debts'!$G$6=0,0,INDEX('Your Debts'!$C$5:$C$12,'Your Debts'!$G$6)/12)),2) | H25: =MIN((I24)+G25,MAX(0,$C25-(E25))) | I25: =ROUND(MAX(0,(I24)+G25-H25),2) | J25: =ROUND((L24)*(IF('Your Debts'!$G$7=0,0,INDEX('Your Debts'!$C$5:$C$12,'Your Debts'!$G$7)/12)),2) | K25: =MIN((L24)+J25,MAX(0,$C25-(E25+H25))) | L25: =ROUND(MAX(0,(L24)+J25-K25),2) | M25: =ROUND((O24)*(IF('Your Debts'!$G$8=0,0,INDEX('Your Debts'!$C$5:$C$12,'Your Debts'!$G$8)/12)),2) | N25: =MIN((O24)+M25,MAX(0,$C25-(E25+H25+K25))) | O25: =ROUND(MAX(0,(O24)+M25-N25),2) | P25: =ROUND((R24)*(IF('Your Debts'!$G$9=0,0,INDEX('Your Debts'!$C$5:$C$12,'Your Debts'!$G$9)/12)),2) | Q25: =MIN((R24)+P25,MAX(0,$C25-(E25+H25+K25+N25))) | R25: =ROUND(MAX(0,(R24)+P25-Q25),2) | S25: =ROUND((U24)*(IF('Your Debts'!$G$10=0,0,INDEX('Your Debts'!$C$5:$C$12,'Your Debts'!$G$10)/12)),2) | T25: =MIN((U24)+S25,MAX(0,$C25-(E25+H25+K25+N25+Q25))) | U25: =ROUND(MAX(0,(U24)+S25-T25),2) | V25: =ROUND((X24)*(IF('Your Debts'!$G$11=0,0,INDEX('Your Debts'!$C$5:$C$12,'Your Debts'!$G$11)/12)),2) | W25: =MIN((X24)+V25,MAX(0,$C25-(E25+H25+K25+N25+Q25+T25))) | X25: =ROUND(MAX(0,(X24)+V25-W25),2) | Y25: =ROUND((AA24)*(IF('Your Debts'!$G$12=0,0,INDEX('Your Debts'!$C$5:$C$12,'Your Debts'!$G$12)/12)),2) | Z25: =MIN((AA24)+Y25,MAX(0,$C25-(E25+H25+K25+N25+Q25+T25+W25))) | AA25: =ROUND(MAX(0,(AA24)+Y25-Z25),2) | AB25: =F25+I25+L25+O25+R25+U25+X25+AA25 | AC25: =AC24+D25+G25+J25+M25+P25+S25+V25+Y25
A26: 21 | B26: =EDATE('Your Debts'!$B$19,20) | C26: ='Your Debts'!$B$18 | D26: =ROUND((F25)*(IF('Your Debts'!$G$5=0,0,INDEX('Your Debts'!$C$5:$C$12,'Your Debts'!$G$5)/12)),2) | E26: =MIN((F25)+D26,MAX(0,$C26-(0))) | F26: =ROUND(MAX(0,(F25)+D26-E26),2) | G26: =ROUND((I25)*(IF('Your Debts'!$G$6=0,0,INDEX('Your Debts'!$C$5:$C$12,'Your Debts'!$G$6)/12)),2) | H26: =MIN((I25)+G26,MAX(0,$C26-(E26))) | I26: =ROUND(MAX(0,(I25)+G26-H26),2) | J26: =ROUND((L25)*(IF('Your Debts'!$G$7=0,0,INDEX('Your Debts'!$C$5:$C$12,'Your Debts'!$G$7)/12)),2) | K26: =MIN((L25)+J26,MAX(0,$C26-(E26+H26))) | L26: =ROUND(MAX(0,(L25)+J26-K26),2) | M26: =ROUND((O25)*(IF('Your Debts'!$G$8=0,0,INDEX('Your Debts'!$C$5:$C$12,'Your Debts'!$G$8)/12)),2) | N26: =MIN((O25)+M26,MAX(0,$C26-(E26+H26+K26))) | O26: =ROUND(MAX(0,(O25)+M26-N26),2) | P26: =ROUND((R25)*(IF('Your Debts'!$G$9=0,0,INDEX('Your Debts'!$C$5:$C$12,'Your Debts'!$G$9)/12)),2) | Q26: =MIN((R25)+P26,MAX(0,$C26-(E26+H26+K26+N26))) | R26: =ROUND(MAX(0,(R25)+P26-Q26),2) | S26: =ROUND((U25)*(IF('Your Debts'!$G$10=0,0,INDEX('Your Debts'!$C$5:$C$12,'Your Debts'!$G$10)/12)),2) | T26: =MIN((U25)+S26,MAX(0,$C26-(E26+H26+K26+N26+Q26))) | U26: =ROUND(MAX(0,(U25)+S26-T26),2) | V26: =ROUND((X25)*(IF('Your Debts'!$G$11=0,0,INDEX('Your Debts'!$C$5:$C$12,'Your Debts'!$G$11)/12)),2) | W26: =MIN((X25)+V26,MAX(0,$C26-(E26+H26+K26+N26+Q26+T26))) | X26: =ROUND(MAX(0,(X25)+V26-W26),2) | Y26: =ROUND((AA25)*(IF('Your Debts'!$G$12=0,0,INDEX('Your Debts'!$C$5:$C$12,'Your Debts'!$G$12)/12)),2) | Z26: =MIN((AA25)+Y26,MAX(0,$C26-(E26+H26+K26+N26+Q26+T26+W26))) | AA26: =ROUND(MAX(0,(AA25)+Y26-Z26),2) | AB26: =F26+I26+L26+O26+R26+U26+X26+AA26 | AC26: =AC25+D26+G26+J26+M26+P26+S26+V26+Y26
A27: 22 | B27: =EDATE('Your Debts'!$B$19,21) | C27: ='Your Debts'!$B$18 | D27: =ROUND((F26)*(IF('Your Debts'!$G$5=0,0,INDEX('Your Debts'!$C$5:$C$12,'Your Debts'!$G$5)/12)),2) | E27: =MIN((F26)+D27,MAX(0,$C27-(0))) | F27: =ROUND(MAX(0,(F26)+D27-E27),2) | G27: =ROUND((I26)*(IF('Your Debts'!$G$6=0,0,INDEX('Your Debts'!$C$5:$C$12,'Your Debts'!$G$6)/12)),2) | H27: =MIN((I26)+G27,MAX(0,$C27-(E27))) | I27: =ROUND(MAX(0,(I26)+G27-H27),2) | J27: =ROUND((L26)*(IF('Your Debts'!$G$7=0,0,INDEX('Your Debts'!$C$5:$C$12,'Your Debts'!$G$7)/12)),2) | K27: =MIN((L26)+J27,MAX(0,$C27-(E27+H27))) | L27: =ROUND(MAX(0,(L26)+J27-K27),2) | M27: =ROUND((O26)*(IF('Your Debts'!$G$8=0,0,INDEX('Your Debts'!$C$5:$C$12,'Your Debts'!$G$8)/12)),2) | N27: =MIN((O26)+M27,MAX(0,$C27-(E27+H27+K27))) | O27: =ROUND(MAX(0,(O26)+M27-N27),2) | P27: =ROUND((R26)*(IF('Your Debts'!$G$9=0,0,INDEX('Your Debts'!$C$5:$C$12,'Your Debts'!$G$9)/12)),2) | Q27: =MIN((R26)+P27,MAX(0,$C27-(E27+H27+K27+N27))) | R27: =ROUND(MAX(0,(R26)+P27-Q27),2) | S27: =ROUND((U26)*(IF('Your Debts'!$G$10=0,0,INDEX('Your Debts'!$C$5:$C$12,'Your Debts'!$G$10)/12)),2) | T27: =MIN((U26)+S27,MAX(0,$C27-(E27+H27+K27+N27+Q27))) | U27: =ROUND(MAX(0,(U26)+S27-T27),2) | V27: =ROUND((X26)*(IF('Your Debts'!$G$11=0,0,INDEX('Your Debts'!$C$5:$C$12,'Your Debts'!$G$11)/12)),2) | W27: =MIN((X26)+V27,MAX(0,$C27-(E27+H27+K27+N27+Q27+T27))) | X27: =ROUND(MAX(0,(X26)+V27-W27),2) | Y27: =ROUND((AA26)*(IF('Your Debts'!$G$12=0,0,INDEX('Your Debts'!$C$5:$C$12,'Your Debts'!$G$12)/12)),2) | Z27: =MIN((AA26)+Y27,MAX(0,$C27-(E27+H27+K27+N27+Q27+T27+W27))) | AA27: =ROUND(MAX(0,(AA26)+Y27-Z27),2) | AB27: =F27+I27+L27+O27+R27+U27+X27+AA27 | AC27: =AC26+D27+G27+J27+M27+P27+S27+V27+Y27
A28: 23 | B28: =EDATE('Your Debts'!$B$19,22) | C28: ='Your Debts'!$B$18 | D28: =ROUND((F27)*(IF('Your Debts'!$G$5=0,0,INDEX('Your Debts'!$C$5:$C$12,'Your Debts'!$G$5)/12)),2) | E28: =MIN((F27)+D28,MAX(0,$C28-(0))) | F28: =ROUND(MAX(0,(F27)+D28-E28),2) | G28: =ROUND((I27)*(IF('Your Debts'!$G$6=0,0,INDEX('Your Debts'!$C$5:$C$12,'Your Debts'!$G$6)/12)),2) | H28: =MIN((I27)+G28,MAX(0,$C28-(E28))) | I28: =ROUND(MAX(0,(I27)+G28-H28),2) | J28: =ROUND((L27)*(IF('Your Debts'!$G$7=0,0,INDEX('Your Debts'!$C$5:$C$12,'Your Debts'!$G$7)/12)),2) | K28: =MIN((L27)+J28,MAX(0,$C28-(E28+H28))) | L28: =ROUND(MAX(0,(L27)+J28-K28),2) | M28: =ROUND((O27)*(IF('Your Debts'!$G$8=0,0,INDEX('Your Debts'!$C$5:$C$12,'Your Debts'!$G$8)/12)),2) | N28: =MIN((O27)+M28,MAX(0,$C28-(E28+H28+K28))) | O28: =ROUND(MAX(0,(O27)+M28-N28),2) | P28: =ROUND((R27)*(IF('Your Debts'!$G$9=0,0,INDEX('Your Debts'!$C$5:$C$12,'Your Debts'!$G$9)/12)),2) | Q28: =MIN((R27)+P28,MAX(0,$C28-(E28+H28+K28+N28))) | R28: =ROUND(MAX(0,(R27)+P28-Q28),2) | S28: =ROUND((U27)*(IF('Your Debts'!$G$10=0,0,INDEX('Your Debts'!$C$5:$C$12,'Your Debts'!$G$10)/12)),2) | T28: =MIN((U27)+S28,MAX(0,$C28-(E28+H28+K28+N28+Q28))) | U28: =ROUND(MAX(0,(U27)+S28-T28),2) | V28: =ROUND((X27)*(IF('Your Debts'!$G$11=0,0,INDEX('Your Debts'!$C$5:$C$12,'Your Debts'!$G$11)/12)),2) | W28: =MIN((X27)+V28,MAX(0,$C28-(E28+H28+K28+N28+Q28+T28))) | X28: =ROUND(MAX(0,(X27)+V28-W28),2) | Y28: =ROUND((AA27)*(IF('Your Debts'!$G$12=0,0,INDEX('Your Debts'!$C$5:$C$12,'Your Debts'!$G$12)/12)),2) | Z28: =MIN((AA27)+Y28,MAX(0,$C28-(E28+H28+K28+N28+Q28+T28+W28))) | AA28: =ROUND(MAX(0,(AA27)+Y28-Z28),2) | AB28: =F28+I28+L28+O28+R28+U28+X28+AA28 | AC28: =AC27+D28+G28+J28+M28+P28+S28+V28+Y28
A29: 24 | B29: =EDATE('Your Debts'!$B$19,23) | C29: ='Your Debts'!$B$18 | D29: =ROUND((F28)*(IF('Your Debts'!$G$5=0,0,INDEX('Your Debts'!$C$5:$C$12,'Your Debts'!$G$5)/12)),2) | E29: =MIN((F28)+D29,MAX(0,$C29-(0))) | F29: =ROUND(MAX(0,(F28)+D29-E29),2) | G29: =ROUND((I28)*(IF('Your Debts'!$G$6=0,0,INDEX('Your Debts'!$C$5:$C$12,'Your Debts'!$G$6)/12)),2) | H29: =MIN((I28)+G29,MAX(0,$C29-(E29))) | I29: =ROUND(MAX(0,(I28)+G29-H29),2) | J29: =ROUND((L28)*(IF('Your Debts'!$G$7=0,0,INDEX('Your Debts'!$C$5:$C$12,'Your Debts'!$G$7)/12)),2) | K29: =MIN((L28)+J29,MAX(0,$C29-(E29+H29))) | L29: =ROUND(MAX(0,(L28)+J29-K29),2) | M29: =ROUND((O28)*(IF('Your Debts'!$G$8=0,0,INDEX('Your Debts'!$C$5:$C$12,'Your Debts'!$G$8)/12)),2) | N29: =MIN((O28)+M29,MAX(0,$C29-(E29+H29+K29))) | O29: =ROUND(MAX(0,(O28)+M29-N29),2) | P29: =ROUND((R28)*(IF('Your Debts'!$G$9=0,0,INDEX('Your Debts'!$C$5:$C$12,'Your Debts'!$G$9)/12)),2) | Q29: =MIN((R28)+P29,MAX(0,$C29-(E29+H29+K29+N29))) | R29: =ROUND(MAX(0,(R28)+P29-Q29),2) | S29: =ROUND((U28)*(IF('Your Debts'!$G$10=0,0,INDEX('Your Debts'!$C$5:$C$12,'Your Debts'!$G$10)/12)),2) | T29: =MIN((U28)+S29,MAX(0,$C29-(E29+H29+K29+N29+Q29))) | U29: =ROUND(MAX(0,(U28)+S29-T29),2) | V29: =ROUND((X28)*(IF('Your Debts'!$G$11=0,0,INDEX('Your Debts'!$C$5:$C$12,'Your Debts'!$G$11)/12)),2) | W29: =MIN((X28)+V29,MAX(0,$C29-(E29+H29+K29+N29+Q29+T29))) | X29: =ROUND(MAX(0,(X28)+V29-W29),2) | Y29: =ROUND((AA28)*(IF('Your Debts'!$G$12=0,0,INDEX('Your Debts'!$C$5:$C$12,'Your Debts'!$G$12)/12)),2) | Z29: =MIN((AA28)+Y29,MAX(0,$C29-(E29+H29+K29+N29+Q29+T29+W29))) | AA29: =ROUND(MAX(0,(AA28)+Y29-Z29),2) | AB29: =F29+I29+L29+O29+R29+U29+X29+AA29 | AC29: =AC28+D29+G29+J29+M29+P29+S29+V29+Y29
A30: 25 | B30: =EDATE('Your Debts'!$B$19,24) | C30: ='Your Debts'!$B$18 | D30: =ROUND((F29)*(IF('Your Debts'!$G$5=0,0,INDEX('Your Debts'!$C$5:$C$12,'Your Debts'!$G$5)/12)),2) | E30: =MIN((F29)+D30,MAX(0,$C30-(0))) | F30: =ROUND(MAX(0,(F29)+D30-E30),2) | G30: =ROUND((I29)*(IF('Your Debts'!$G$6=0,0,INDEX('Your Debts'!$C$5:$C$12,'Your Debts'!$G$6)/12)),2) | H30: =MIN((I29)+G30,MAX(0,$C30-(E30))) | I30: =ROUND(MAX(0,(I29)+G30-H30),2) | J30: =ROUND((L29)*(IF('Your Debts'!$G$7=0,0,INDEX('Your Debts'!$C$5:$C$12,'Your Debts'!$G$7)/12)),2) | K30: =MIN((L29)+J30,MAX(0,$C30-(E30+H30))) | L30: =ROUND(MAX(0,(L29)+J30-K30),2) | M30: =ROUND((O29)*(IF('Your Debts'!$G$8=0,0,INDEX('Your Debts'!$C$5:$C$12,'Your Debts'!$G$8)/12)),2) | N30: =MIN((O29)+M30,MAX(0,$C30-(E30+H30+K30))) | O30: =ROUND(MAX(0,(O29)+M30-N30),2) | P30: =ROUND((R29)*(IF('Your Debts'!$G$9=0,0,INDEX('Your Debts'!$C$5:$C$12,'Your Debts'!$G$9)/12)),2) | Q30: =MIN((R29)+P30,MAX(0,$C30-(E30+H30+K30+N30))) | R30: =ROUND(MAX(0,(R29)+P30-Q30),2) | S30: =ROUND((U29)*(IF('Your Debts'!$G$10=0,0,INDEX('Your Debts'!$C$5:$C$12,'Your Debts'!$G$10)/12)),2) | T30: =MIN((U29)+S30,MAX(0,$C30-(E30+H30+K30+N30+Q30))) | U30: =ROUND(MAX(0,(U29)+S30-T30),2) | V30: =ROUND((X29)*(IF('Your Debts'!$G$11=0,0,INDEX('Your Debts'!$C$5:$C$12,'Your Debts'!$G$11)/12)),2) | W30: =MIN((X29)+V30,MAX(0,$C30-(E30+H30+K30+N30+Q30+T30))) | X30: =ROUND(MAX(0,(X29)+V30-W30),2) | Y30: =ROUND((AA29)*(IF('Your Debts'!$G$12=0,0,INDEX('Your Debts'!$C$5:$C$12,'Your Debts'!$G$12)/12)),2) | Z30: =MIN((AA29)+Y30,MAX(0,$C30-(E30+H30+K30+N30+Q30+T30+W30))) | AA30: =ROUND(MAX(0,(AA29)+Y30-Z30),2) | AB30: =F30+I30+L30+O30+R30+U30+X30+AA30 | AC30: =AC29+D30+G30+J30+M30+P30+S30+V30+Y30
A31: 26 | B31: =EDATE('Your Debts'!$B$19,25) | C31: ='Your Debts'!$B$18 | D31: =ROUND((F30)*(IF('Your Debts'!$G$5=0,0,INDEX('Your Debts'!$C$5:$C$12,'Your Debts'!$G$5)/12)),2) | E31: =MIN((F30)+D31,MAX(0,$C31-(0))) | F31: =ROUND(MAX(0,(F30)+D31-E31),2) | G31: =ROUND((I30)*(IF('Your Debts'!$G$6=0,0,INDEX('Your Debts'!$C$5:$C$12,'Your Debts'!$G$6)/12)),2) | H31: =MIN((I30)+G31,MAX(0,$C31-(E31))) | I31: =ROUND(MAX(0,(I30)+G31-H31),2) | J31: =ROUND((L30)*(IF('Your Debts'!$G$7=0,0,INDEX('Your Debts'!$C$5:$C$12,'Your Debts'!$G$7)/12)),2) | K31: =MIN((L30)+J31,MAX(0,$C31-(E31+H31))) | L31: =ROUND(MAX(0,(L30)+J31-K31),2) | M31: =ROUND((O30)*(IF('Your Debts'!$G$8=0,0,INDEX('Your Debts'!$C$5:$C$12,'Your Debts'!$G$8)/12)),2) | N31: =MIN((O30)+M31,MAX(0,$C31-(E31+H31+K31))) | O31: =ROUND(MAX(0,(O30)+M31-N31),2) | P31: =ROUND((R30)*(IF('Your Debts'!$G$9=0,0,INDEX('Your Debts'!$C$5:$C$12,'Your Debts'!$G$9)/12)),2) | Q31: =MIN((R30)+P31,MAX(0,$C31-(E31+H31+K31+N31))) | R31: =ROUND(MAX(0,(R30)+P31-Q31),2) | S31: =ROUND((U30)*(IF('Your Debts'!$G$10=0,0,INDEX('Your Debts'!$C$5:$C$12,'Your Debts'!$G$10)/12)),2) | T31: =MIN((U30)+S31,MAX(0,$C31-(E31+H31+K31+N31+Q31))) | U31: =ROUND(MAX(0,(U30)+S31-T31),2) | V31: =ROUND((X30)*(IF('Your Debts'!$G$11=0,0,INDEX('Your Debts'!$C$5:$C$12,'Your Debts'!$G$11)/12)),2) | W31: =MIN((X30)+V31,MAX(0,$C31-(E31+H31+K31+N31+Q31+T31))) | X31: =ROUND(MAX(0,(X30)+V31-W31),2) | Y31: =ROUND((AA30)*(IF('Your Debts'!$G$12=0,0,INDEX('Your Debts'!$C$5:$C$12,'Your Debts'!$G$12)/12)),2) | Z31: =MIN((AA30)+Y31,MAX(0,$C31-(E31+H31+K31+N31+Q31+T31+W31))) | AA31: =ROUND(MAX(0,(AA30)+Y31-Z31),2) | AB31: =F31+I31+L31+O31+R31+U31+X31+AA31 | AC31: =AC30+D31+G31+J31+M31+P31+S31+V31+Y31
A32: 27 | B32: =EDATE('Your Debts'!$B$19,26) | C32: ='Your Debts'!$B$18 | D32: =ROUND((F31)*(IF('Your Debts'!$G$5=0,0,INDEX('Your Debts'!$C$5:$C$12,'Your Debts'!$G$5)/12)),2) | E32: =MIN((F31)+D32,MAX(0,$C32-(0))) | F32: =ROUND(MAX(0,(F31)+D32-E32),2) | G32: =ROUND((I31)*(IF('Your Debts'!$G$6=0,0,INDEX('Your Debts'!$C$5:$C$12,'Your Debts'!$G$6)/12)),2) | H32: =MIN((I31)+G32,MAX(0,$C32-(E32))) | I32: =ROUND(MAX(0,(I31)+G32-H32),2) | J32: =ROUND((L31)*(IF('Your Debts'!$G$7=0,0,INDEX('Your Debts'!$C$5:$C$12,'Your Debts'!$G$7)/12)),2) | K32: =MIN((L31)+J32,MAX(0,$C32-(E32+H32))) | L32: =ROUND(MAX(0,(L31)+J32-K32),2) | M32: =ROUND((O31)*(IF('Your Debts'!$G$8=0,0,INDEX('Your Debts'!$C$5:$C$12,'Your Debts'!$G$8)/12)),2) | N32: =MIN((O31)+M32,MAX(0,$C32-(E32+H32+K32))) | O32: =ROUND(MAX(0,(O31)+M32-N32),2) | P32: =ROUND((R31)*(IF('Your Debts'!$G$9=0,0,INDEX('Your Debts'!$C$5:$C$12,'Your Debts'!$G$9)/12)),2) | Q32: =MIN((R31)+P32,MAX(0,$C32-(E32+H32+K32+N32))) | R32: =ROUND(MAX(0,(R31)+P32-Q32),2) | S32: =ROUND((U31)*(IF('Your Debts'!$G$10=0,0,INDEX('Your Debts'!$C$5:$C$12,'Your Debts'!$G$10)/12)),2) | T32: =MIN((U31)+S32,MAX(0,$C32-(E32+H32+K32+N32+Q32))) | U32: =ROUND(MAX(0,(U31)+S32-T32),2) | V32: =ROUND((X31)*(IF('Your Debts'!$G$11=0,0,INDEX('Your Debts'!$C$5:$C$12,'Your Debts'!$G$11)/12)),2) | W32: =MIN((X31)+V32,MAX(0,$C32-(E32+H32+K32+N32+Q32+T32))) | X32: =ROUND(MAX(0,(X31)+V32-W32),2) | Y32: =ROUND((AA31)*(IF('Your Debts'!$G$12=0,0,INDEX('Your Debts'!$C$5:$C$12,'Your Debts'!$G$12)/12)),2) | Z32: =MIN((AA31)+Y32,MAX(0,$C32-(E32+H32+K32+N32+Q32+T32+W32))) | AA32: =ROUND(MAX(0,(AA31)+Y32-Z32),2) | AB32: =F32+I32+L32+O32+R32+U32+X32+AA32 | AC32: =AC31+D32+G32+J32+M32+P32+S32+V32+Y32
A33: 28 | B33: =EDATE('Your Debts'!$B$19,27) | C33: ='Your Debts'!$B$18 | D33: =ROUND((F32)*(IF('Your Debts'!$G$5=0,0,INDEX('Your Debts'!$C$5:$C$12,'Your Debts'!$G$5)/12)),2) | E33: =MIN((F32)+D33,MAX(0,$C33-(0))) | F33: =ROUND(MAX(0,(F32)+D33-E33),2) | G33: =ROUND((I32)*(IF('Your Debts'!$G$6=0,0,INDEX('Your Debts'!$C$5:$C$12,'Your Debts'!$G$6)/12)),2) | H33: =MIN((I32)+G33,MAX(0,$C33-(E33))) | I33: =ROUND(MAX(0,(I32)+G33-H33),2) | J33: =ROUND((L32)*(IF('Your Debts'!$G$7=0,0,INDEX('Your Debts'!$C$5:$C$12,'Your Debts'!$G$7)/12)),2) | K33: =MIN((L32)+J33,MAX(0,$C33-(E33+H33))) | L33: =ROUND(MAX(0,(L32)+J33-K33),2) | M33: =ROUND((O32)*(IF('Your Debts'!$G$8=0,0,INDEX('Your Debts'!$C$5:$C$12,'Your Debts'!$G$8)/12)),2) | N33: =MIN((O32)+M33,MAX(0,$C33-(E33+H33+K33))) | O33: =ROUND(MAX(0,(O32)+M33-N33),2) | P33: =ROUND((R32)*(IF('Your Debts'!$G$9=0,0,INDEX('Your Debts'!$C$5:$C$12,'Your Debts'!$G$9)/12)),2) | Q33: =MIN((R32)+P33,MAX(0,$C33-(E33+H33+K33+N33))) | R33: =ROUND(MAX(0,(R32)+P33-Q33),2) | S33: =ROUND((U32)*(IF('Your Debts'!$G$10=0,0,INDEX('Your Debts'!$C$5:$C$12,'Your Debts'!$G$10)/12)),2) | T33: =MIN((U32)+S33,MAX(0,$C33-(E33+H33+K33+N33+Q33))) | U33: =ROUND(MAX(0,(U32)+S33-T33),2) | V33: =ROUND((X32)*(IF('Your Debts'!$G$11=0,0,INDEX('Your Debts'!$C$5:$C$12,'Your Debts'!$G$11)/12)),2) | W33: =MIN((X32)+V33,MAX(0,$C33-(E33+H33+K33+N33+Q33+T33))) | X33: =ROUND(MAX(0,(X32)+V33-W33),2) | Y33: =ROUND((AA32)*(IF('Your Debts'!$G$12=0,0,INDEX('Your Debts'!$C$5:$C$12,'Your Debts'!$G$12)/12)),2) | Z33: =MIN((AA32)+Y33,MAX(0,$C33-(E33+H33+K33+N33+Q33+T33+W33))) | AA33: =ROUND(MAX(0,(AA32)+Y33-Z33),2) | AB33: =F33+I33+L33+O33+R33+U33+X33+AA33 | AC33: =AC32+D33+G33+J33+M33+P33+S33+V33+Y33
A34: 29 | B34: =EDATE('Your Debts'!$B$19,28) | C34: ='Your Debts'!$B$18 | D34: =ROUND((F33)*(IF('Your Debts'!$G$5=0,0,INDEX('Your Debts'!$C$5:$C$12,'Your Debts'!$G$5)/12)),2) | E34: =MIN((F33)+D34,MAX(0,$C34-(0))) | F34: =ROUND(MAX(0,(F33)+D34-E34),2) | G34: =ROUND((I33)*(IF('Your Debts'!$G$6=0,0,INDEX('Your Debts'!$C$5:$C$12,'Your Debts'!$G$6)/12)),2) | H34: =MIN((I33)+G34,MAX(0,$C34-(E34))) | I34: =ROUND(MAX(0,(I33)+G34-H34),2) | J34: =ROUND((L33)*(IF('Your Debts'!$G$7=0,0,INDEX('Your Debts'!$C$5:$C$12,'Your Debts'!$G$7)/12)),2) | K34: =MIN((L33)+J34,MAX(0,$C34-(E34+H34))) | L34: =ROUND(MAX(0,(L33)+J34-K34),2) | M34: =ROUND((O33)*(IF('Your Debts'!$G$8=0,0,INDEX('Your Debts'!$C$5:$C$12,'Your Debts'!$G$8)/12)),2) | N34: =MIN((O33)+M34,MAX(0,$C34-(E34+H34+K34))) | O34: =ROUND(MAX(0,(O33)+M34-N34),2) | P34: =ROUND((R33)*(IF('Your Debts'!$G$9=0,0,INDEX('Your Debts'!$C$5:$C$12,'Your Debts'!$G$9)/12)),2) | Q34: =MIN((R33)+P34,MAX(0,$C34-(E34+H34+K34+N34))) | R34: =ROUND(MAX(0,(R33)+P34-Q34),2) | S34: =ROUND((U33)*(IF('Your Debts'!$G$10=0,0,INDEX('Your Debts'!$C$5:$C$12,'Your Debts'!$G$10)/12)),2) | T34: =MIN((U33)+S34,MAX(0,$C34-(E34+H34+K34+N34+Q34))) | U34: =ROUND(MAX(0,(U33)+S34-T34),2) | V34: =ROUND((X33)*(IF('Your Debts'!$G$11=0,0,INDEX('Your Debts'!$C$5:$C$12,'Your Debts'!$G$11)/12)),2) | W34: =MIN((X33)+V34,MAX(0,$C34-(E34+H34+K34+N34+Q34+T34))) | X34: =ROUND(MAX(0,(X33)+V34-W34),2) | Y34: =ROUND((AA33)*(IF('Your Debts'!$G$12=0,0,INDEX('Your Debts'!$C$5:$C$12,'Your Debts'!$G$12)/12)),2) | Z34: =MIN((AA33)+Y34,MAX(0,$C34-(E34+H34+K34+N34+Q34+T34+W34))) | AA34: =ROUND(MAX(0,(AA33)+Y34-Z34),2) | AB34: =F34+I34+L34+O34+R34+U34+X34+AA34 | AC34: =AC33+D34+G34+J34+M34+P34+S34+V34+Y34
A35: 30 | B35: =EDATE('Your Debts'!$B$19,29) | C35: ='Your Debts'!$B$18 | D35: =ROUND((F34)*(IF('Your Debts'!$G$5=0,0,INDEX('Your Debts'!$C$5:$C$12,'Your Debts'!$G$5)/12)),2) | E35: =MIN((F34)+D35,MAX(0,$C35-(0))) | F35: =ROUND(MAX(0,(F34)+D35-E35),2) | G35: =ROUND((I34)*(IF('Your Debts'!$G$6=0,0,INDEX('Your Debts'!$C$5:$C$12,'Your Debts'!$G$6)/12)),2) | H35: =MIN((I34)+G35,MAX(0,$C35-(E35))) | I35: =ROUND(MAX(0,(I34)+G35-H35),2) | J35: =ROUND((L34)*(IF('Your Debts'!$G$7=0,0,INDEX('Your Debts'!$C$5:$C$12,'Your Debts'!$G$7)/12)),2) | K35: =MIN((L34)+J35,MAX(0,$C35-(E35+H35))) | L35: =ROUND(MAX(0,(L34)+J35-K35),2) | M35: =ROUND((O34)*(IF('Your Debts'!$G$8=0,0,INDEX('Your Debts'!$C$5:$C$12,'Your Debts'!$G$8)/12)),2) | N35: =MIN((O34)+M35,MAX(0,$C35-(E35+H35+K35))) | O35: =ROUND(MAX(0,(O34)+M35-N35),2) | P35: =ROUND((R34)*(IF('Your Debts'!$G$9=0,0,INDEX('Your Debts'!$C$5:$C$12,'Your Debts'!$G$9)/12)),2) | Q35: =MIN((R34)+P35,MAX(0,$C35-(E35+H35+K35+N35))) | R35: =ROUND(MAX(0,(R34)+P35-Q35),2) | S35: =ROUND((U34)*(IF('Your Debts'!$G$10=0,0,INDEX('Your Debts'!$C$5:$C$12,'Your Debts'!$G$10)/12)),2) | T35: =MIN((U34)+S35,MAX(0,$C35-(E35+H35+K35+N35+Q35))) | U35: =ROUND(MAX(0,(U34)+S35-T35),2) | V35: =ROUND((X34)*(IF('Your Debts'!$G$11=0,0,INDEX('Your Debts'!$C$5:$C$12,'Your Debts'!$G$11)/12)),2) | W35: =MIN((X34)+V35,MAX(0,$C35-(E35+H35+K35+N35+Q35+T35))) | X35: =ROUND(MAX(0,(X34)+V35-W35),2) | Y35: =ROUND((AA34)*(IF('Your Debts'!$G$12=0,0,INDEX('Your Debts'!$C$5:$C$12,'Your Debts'!$G$12)/12)),2) | Z35: =MIN((AA34)+Y35,MAX(0,$C35-(E35+H35+K35+N35+Q35+T35+W35))) | AA35: =ROUND(MAX(0,(AA34)+Y35-Z35),2) | AB35: =F35+I35+L35+O35+R35+U35+X35+AA35 | AC35: =AC34+D35+G35+J35+M35+P35+S35+V35+Y35
A36: 31 | B36: =EDATE('Your Debts'!$B$19,30) | C36: ='Your Debts'!$B$18 | D36: =ROUND((F35)*(IF('Your Debts'!$G$5=0,0,INDEX('Your Debts'!$C$5:$C$12,'Your Debts'!$G$5)/12)),2) | E36: =MIN((F35)+D36,MAX(0,$C36-(0))) | F36: =ROUND(MAX(0,(F35)+D36-E36),2) | G36: =ROUND((I35)*(IF('Your Debts'!$G$6=0,0,INDEX('Your Debts'!$C$5:$C$12,'Your Debts'!$G$6)/12)),2) | H36: =MIN((I35)+G36,MAX(0,$C36-(E36))) | I36: =ROUND(MAX(0,(I35)+G36-H36),2) | J36: =ROUND((L35)*(IF('Your Debts'!$G$7=0,0,INDEX('Your Debts'!$C$5:$C$12,'Your Debts'!$G$7)/12)),2) | K36: =MIN((L35)+J36,MAX(0,$C36-(E36+H36))) | L36: =ROUND(MAX(0,(L35)+J36-K36),2) | M36: =ROUND((O35)*(IF('Your Debts'!$G$8=0,0,INDEX('Your Debts'!$C$5:$C$12,'Your Debts'!$G$8)/12)),2) | N36: =MIN((O35)+M36,MAX(0,$C36-(E36+H36+K36))) | O36: =ROUND(MAX(0,(O35)+M36-N36),2) | P36: =ROUND((R35)*(IF('Your Debts'!$G$9=0,0,INDEX('Your Debts'!$C$5:$C$12,'Your Debts'!$G$9)/12)),2) | Q36: =MIN((R35)+P36,MAX(0,$C36-(E36+H36+K36+N36))) | R36: =ROUND(MAX(0,(R35)+P36-Q36),2) | S36: =ROUND((U35)*(IF('Your Debts'!$G$10=0,0,INDEX('Your Debts'!$C$5:$C$12,'Your Debts'!$G$10)/12)),2) | T36: =MIN((U35)+S36,MAX(0,$C36-(E36+H36+K36+N36+Q36))) | U36: =ROUND(MAX(0,(U35)+S36-T36),2) | V36: =ROUND((X35)*(IF('Your Debts'!$G$11=0,0,INDEX('Your Debts'!$C$5:$C$12,'Your Debts'!$G$11)/12)),2) | W36: =MIN((X35)+V36,MAX(0,$C36-(E36+H36+K36+N36+Q36+T36))) | X36: =ROUND(MAX(0,(X35)+V36-W36),2) | Y36: =ROUND((AA35)*(IF('Your Debts'!$G$12=0,0,INDEX('Your Debts'!$C$5:$C$12,'Your Debts'!$G$12)/12)),2) | Z36: =MIN((AA35)+Y36,MAX(0,$C36-(E36+H36+K36+N36+Q36+T36+W36))) | AA36: =ROUND(MAX(0,(AA35)+Y36-Z36),2) | AB36: =F36+I36+L36+O36+R36+U36+X36+AA36 | AC36: =AC35+D36+G36+J36+M36+P36+S36+V36+Y36
